2024-06-08 23:12:06,744 - pyswarms.single.global_best - INFO - Optimize for 100 iters with {'c1': 0.5, 'c2': 0.3, 'w': 0.9}
2024-06-08 23:13:26,642 - pyswarms.single.global_best - INFO - Optimize for 100 iters with {'c1': 0.5, 'c2': 0.3, 'w': 0.9}
2024-06-08 23:14:05,187 - pyswarms.single.global_best - INFO - Optimize for 100 iters with {'c1': 0.5, 'c2': 0.3, 'w': 0.9}
2024-06-08 23:14:07,044 - pyswarms.single.global_best - INFO - Optimization finished | best cost: 66.66666666666667, best pos: [   28.26391725 10721.13757517]
2024-06-08 23:26:07,221 - pyswarms.single.global_best - INFO - Optimize for 10 iters with {'c1': 0.5, 'c2': 0.3, 'w': 0.9}
2024-06-08 23:26:07,610 - pyswarms.single.global_best - INFO - Optimization finished | best cost: 66.66666666666667, best pos: [4.61970268e+01 5.20573022e+04]
2024-06-08 23:39:49,953 - pyswarms.single.global_best - INFO - Optimize for 10 iters with {'c1': 0.5, 'c2': 0.3, 'w': 0.9}
2024-06-08 23:41:01,355 - pyswarms.single.global_best - INFO - Optimize for 10 iters with {'c1': 0.5, 'c2': 0.3, 'w': 0.9}
2024-06-08 23:43:36,933 - pyswarms.single.global_best - INFO - Optimize for 10 iters with {'c1': 0.5, 'c2': 0.3, 'w': 0.9}
2024-06-08 23:48:48,449 - pyswarms.single.global_best - INFO - Optimize for 10 iters with {'c1': 0.5, 'c2': 0.3, 'w': 0.9}
2024-06-08 23:49:07,318 - pyswarms.single.global_best - INFO - Optimize for 100 iters with {'c1': 0.5, 'c2': 0.3, 'w': 0.9}
2024-06-08 23:50:19,179 - pyswarms.single.global_best - INFO - Optimize for 100 iters with {'c1': 0.5, 'c2': 0.3, 'w': 0.9}
2024-06-08 23:51:01,532 - pyswarms.single.global_best - INFO - Optimize for 100 iters with {'c1': 0.5, 'c2': 0.3, 'w': 0.9}
2024-06-08 23:52:23,966 - pyswarms.single.global_best - INFO - Optimize for 100 iters with {'c1': 0.5, 'c2': 0.3, 'w': 0.9}
2024-06-08 23:53:07,617 - pyswarms.single.global_best - INFO - Optimize for 100 iters with {'c1': 0.5, 'c2': 0.3, 'w': 0.9}
2024-06-09 00:01:17,774 - pyswarms.single.global_best - INFO - Optimize for 100 iters with {'c1': 0.5, 'c2': 0.3, 'w': 0.9}
2024-06-09 00:02:18,563 - pyswarms.single.global_best - INFO - Optimize for 100 iters with {'c1': 0.5, 'c2': 0.3, 'w': 0.9}
2024-06-09 00:03:06,665 - pyswarms.single.global_best - INFO - Optimize for 100 iters with {'c1': 0.5, 'c2': 0.3, 'w': 0.9}
2024-06-09 00:04:19,437 - pyswarms.single.global_best - INFO - Optimize for 100 iters with {'c1': 0.5, 'c2': 0.3, 'w': 0.9}
2024-06-09 00:13:31,653 - pyswarms.single.global_best - INFO - Optimize for 100 iters with {'c1': 0.5, 'c2': 0.3, 'w': 0.9}
2024-06-09 00:14:35,878 - pyswarms.single.global_best - INFO - Optimize for 100 iters with {'c1': 0.5, 'c2': 0.3, 'w': 0.9}
2024-06-09 00:14:37,072 - pyswarms.single.global_best - INFO - Optimization finished | best cost: 66.77666666666667, best pos: [   5.14279993 2320.01104187]
2024-06-09 00:15:21,472 - pyswarms.single.global_best - INFO - Optimize for 100 iters with {'c1': 0.5, 'c2': 0.3, 'w': 0.9}
2024-06-09 00:15:22,593 - pyswarms.single.global_best - INFO - Optimization finished | best cost: 676.7766666666666, best pos: [5.55219432 4.20319685]
2024-06-09 00:16:12,301 - pyswarms.single.global_best - INFO - Optimize for 300 iters with {'c1': 0.5, 'c2': 0.3, 'w': 0.9}
2024-06-09 00:16:14,622 - pyswarms.single.global_best - INFO - Optimization finished | best cost: 672.7766666666666, best pos: [5.11735517 1.38445928]
2024-06-09 00:16:19,564 - pyswarms.single.global_best - INFO - Optimize for 300 iters with {'c1': 0.5, 'c2': 0.3, 'w': 0.9}
2024-06-09 00:16:21,738 - pyswarms.single.global_best - INFO - Optimization finished | best cost: 672.7766666666666, best pos: [2.58327789 3.17110325]
2024-06-09 00:17:22,150 - pyswarms.single.global_best - INFO - Optimize for 300 iters with {'c1': 0.5, 'c2': 0.3, 'w': 0.9}
2024-06-09 00:17:24,335 - pyswarms.single.global_best - INFO - Optimization finished | best cost: 674.7766666666666, best pos: [3.41647364 4.83657223]
2024-06-09 00:17:31,264 - pyswarms.single.global_best - INFO - Optimize for 300 iters with {'c1': 0.5, 'c2': 0.3, 'w': 0.9}
2024-06-09 00:17:33,476 - pyswarms.single.global_best - INFO - Optimization finished | best cost: 679.7766666666666, best pos: [12.44414652  1.005133  ]
2024-06-09 00:17:47,386 - pyswarms.single.global_best - INFO - Optimize for 300 iters with {'c1': 0.5, 'c2': 0.3, 'w': 0.9}
2024-06-09 00:17:49,603 - pyswarms.single.global_best - INFO - Optimization finished | best cost: 671.7766666666666, best pos: [4.22084012 1.39934223]
2024-06-09 00:18:43,459 - pyswarms.single.global_best - INFO - Optimize for 400 iters with {'c1': 0.5, 'c2': 0.3, 'w': 0.9}
2024-06-09 00:20:26,375 - pyswarms.single.global_best - INFO - Optimize for 400 iters with {'c1': 0.5, 'c2': 0.3, 'w': 0.9}
2024-06-09 00:20:29,172 - pyswarms.single.global_best - INFO - Optimization finished | best cost: 685.7766666666666, best pos: [ 8.46254433 11.30651469]
2024-06-09 00:20:48,517 - pyswarms.single.global_best - INFO - Optimize for 400 iters with {'c1': 0.5, 'c2': 0.3, 'w': 0.9}
2024-06-09 00:20:51,338 - pyswarms.single.global_best - INFO - Optimization finished | best cost: 681.7766666666666, best pos: [ 3.69462581 11.13256969]
2024-06-09 00:23:33,026 - pyswarms.single.global_best - INFO - Optimize for 400 iters with {'c1': 0.5, 'c2': 0.3, 'w': 0.9}
2024-06-09 00:23:35,881 - pyswarms.single.global_best - INFO - Optimization finished | best cost: 338.6383333333333, best pos: [ 9.84039864 10.81825309]
2024-06-09 00:24:01,437 - pyswarms.single.global_best - INFO - Optimize for 400 iters with {'c1': 0.5, 'c2': 0.3, 'w': 0.9}
2024-06-09 00:24:04,201 - pyswarms.single.global_best - INFO - Optimization finished | best cost: 337.6383333333333, best pos: [ 7.25332018 10.23656906]
2024-06-09 00:26:37,046 - pyswarms.single.global_best - INFO - Optimize for 400 iters with {'c1': 0.5, 'c2': 0.3, 'w': 0.9}
2024-06-09 00:26:40,000 - pyswarms.single.global_best - INFO - Optimization finished | best cost: 337.1383333333333, best pos: [ 3.95921198 11.45011464]
2024-06-09 00:26:59,962 - pyswarms.single.global_best - INFO - Optimize for 400 iters with {'c1': 0.5, 'c2': 0.3, 'w': 0.9}
2024-06-09 00:27:02,964 - pyswarms.single.global_best - INFO - Optimization finished | best cost: 338.3883333333333, best pos: [ 3.22216444 17.33936151]
2024-06-09 00:27:34,190 - pyswarms.single.global_best - INFO - Optimize for 400 iters with {'c1': 0.5, 'c2': 0.3, 'w': 0.9}
2024-06-09 00:27:37,072 - pyswarms.single.global_best - INFO - Optimization finished | best cost: 208.533, best pos: [14.58532351 10.04127101]
2024-06-09 00:28:02,091 - pyswarms.single.global_best - INFO - Optimize for 400 iters with {'c1': 0.5, 'c2': 0.3, 'w': 0.9}
2024-06-09 00:28:04,932 - pyswarms.single.global_best - INFO - Optimization finished | best cost: 205.833, best pos: [ 5.87209965 10.31962616]
2024-06-09 00:29:14,836 - pyswarms.single.global_best - INFO - Optimize for 400 iters with {'c1': 0.5, 'c2': 0.3, 'w': 0.9}
2024-06-09 00:29:17,663 - pyswarms.single.global_best - INFO - Optimization finished | best cost: 685.7766666666666, best pos: [ 9.30173253 10.16402889]
2024-06-09 00:29:25,897 - pyswarms.single.global_best - INFO - Optimize for 400 iters with {'c1': 0.5, 'c2': 0.3, 'w': 0.9}
2024-06-09 00:29:28,715 - pyswarms.single.global_best - INFO - Optimization finished | best cost: 683.7766666666666, best pos: [ 7.38353015 10.4863234 ]
2024-06-09 00:30:10,984 - pyswarms.single.global_best - INFO - Optimize for 400 iters with {'c1': 0.5, 'c2': 0.3, 'w': 0.9}
2024-06-09 00:30:17,298 - root - ERROR - KeyboardInterrupt while sending command.
Traceback (most recent call last):
  File "/Users/leandrohoenen/PycharmProjects/pso-virtual-machine-resource-optimizer/.venv/lib/python3.12/site-packages/py4j/java_gateway.py", line 1038, in send_command
    response = connection.send_command(command)
               ^^^^^^^^^^^^^^^^^^^^^^^^^^^^^^^^
  File "/Users/leandrohoenen/PycharmProjects/pso-virtual-machine-resource-optimizer/.venv/lib/python3.12/site-packages/py4j/java_gateway.py", line 1217, in send_command
    answer = smart_decode(self.stream.readline()[:-1])
                          ^^^^^^^^^^^^^^^^^^^^^^
  File "/Library/Frameworks/Python.framework/Versions/3.12/lib/python3.12/socket.py", line 707, in readinto
    return self._sock.recv_into(b)
           ^^^^^^^^^^^^^^^^^^^^^^^
KeyboardInterrupt
2024-06-09 00:30:39,367 - pyswarms.single.global_best - INFO - Optimize for 400 iters with {'c1': 0.5, 'c2': 0.3, 'w': 0.9}
2024-06-09 00:30:50,136 - root - ERROR - KeyboardInterrupt while sending command.
Traceback (most recent call last):
  File "/Users/leandrohoenen/PycharmProjects/pso-virtual-machine-resource-optimizer/.venv/lib/python3.12/site-packages/py4j/java_gateway.py", line 1038, in send_command
    response = connection.send_command(command)
               ^^^^^^^^^^^^^^^^^^^^^^^^^^^^^^^^
  File "/Users/leandrohoenen/PycharmProjects/pso-virtual-machine-resource-optimizer/.venv/lib/python3.12/site-packages/py4j/java_gateway.py", line 1217, in send_command
    answer = smart_decode(self.stream.readline()[:-1])
                          ^^^^^^^^^^^^^^^^^^^^^^
  File "/Library/Frameworks/Python.framework/Versions/3.12/lib/python3.12/socket.py", line 707, in readinto
    return self._sock.recv_into(b)
           ^^^^^^^^^^^^^^^^^^^^^^^
KeyboardInterrupt
2024-06-09 00:31:09,927 - pyswarms.single.global_best - INFO - Optimize for 400 iters with {'c1': 0.5, 'c2': 0.3, 'w': 0.9}
2024-06-09 00:31:27,621 - py4j.java_gateway - INFO - Error while receiving.
Traceback (most recent call last):
  File "/Users/leandrohoenen/PycharmProjects/pso-virtual-machine-resource-optimizer/.venv/lib/python3.12/site-packages/py4j/java_gateway.py", line 1224, in send_command
    raise Py4JNetworkError("Answer from Java side is empty")
py4j.protocol.Py4JNetworkError: Answer from Java side is empty
2024-06-09 00:31:27,624 - root - ERROR - Exception while sending command.
Traceback (most recent call last):
  File "/Users/leandrohoenen/PycharmProjects/pso-virtual-machine-resource-optimizer/.venv/lib/python3.12/site-packages/py4j/java_gateway.py", line 1224, in send_command
    raise Py4JNetworkError("Answer from Java side is empty")
py4j.protocol.Py4JNetworkError: Answer from Java side is empty

During handling of the above exception, another exception occurred:

Traceback (most recent call last):
  File "/Users/leandrohoenen/PycharmProjects/pso-virtual-machine-resource-optimizer/.venv/lib/python3.12/site-packages/py4j/java_gateway.py", line 1038, in send_command
    response = connection.send_command(command)
               ^^^^^^^^^^^^^^^^^^^^^^^^^^^^^^^^
  File "/Users/leandrohoenen/PycharmProjects/pso-virtual-machine-resource-optimizer/.venv/lib/python3.12/site-packages/py4j/java_gateway.py", line 1228, in send_command
    raise Py4JNetworkError(
py4j.protocol.Py4JNetworkError: Error while receiving
2024-06-09 00:31:27,625 - py4j.java_gateway - ERROR - An error occurred while trying to connect to the Java server (127.0.0.1:25333)
Traceback (most recent call last):
  File "/Users/leandrohoenen/PycharmProjects/pso-virtual-machine-resource-optimizer/.venv/lib/python3.12/site-packages/py4j/java_gateway.py", line 982, in _get_connection
    connection = self.deque.pop()
                 ^^^^^^^^^^^^^^^^
IndexError: pop from an empty deque

During handling of the above exception, another exception occurred:

Traceback (most recent call last):
  File "/Users/leandrohoenen/PycharmProjects/pso-virtual-machine-resource-optimizer/.venv/lib/python3.12/site-packages/py4j/java_gateway.py", line 1132, in start
    self.socket.connect((self.address, self.port))
ConnectionRefusedError: [Errno 61] Connection refused
2024-06-09 00:31:27,625 - py4j.java_gateway - ERROR - An error occurred while trying to connect to the Java server (127.0.0.1:25333)
Traceback (most recent call last):
  File "/Users/leandrohoenen/PycharmProjects/pso-virtual-machine-resource-optimizer/.venv/lib/python3.12/site-packages/py4j/java_gateway.py", line 982, in _get_connection
    connection = self.deque.pop()
                 ^^^^^^^^^^^^^^^^
IndexError: pop from an empty deque

During handling of the above exception, another exception occurred:

Traceback (most recent call last):
  File "/Users/leandrohoenen/PycharmProjects/pso-virtual-machine-resource-optimizer/.venv/lib/python3.12/site-packages/py4j/java_gateway.py", line 1132, in start
    self.socket.connect((self.address, self.port))
ConnectionRefusedError: [Errno 61] Connection refused
2024-06-09 00:31:27,626 - py4j.java_gateway - ERROR - An error occurred while trying to connect to the Java server (127.0.0.1:25333)
Traceback (most recent call last):
  File "/Users/leandrohoenen/PycharmProjects/pso-virtual-machine-resource-optimizer/.venv/lib/python3.12/site-packages/py4j/java_gateway.py", line 982, in _get_connection
    connection = self.deque.pop()
                 ^^^^^^^^^^^^^^^^
IndexError: pop from an empty deque

During handling of the above exception, another exception occurred:

Traceback (most recent call last):
  File "/Users/leandrohoenen/PycharmProjects/pso-virtual-machine-resource-optimizer/.venv/lib/python3.12/site-packages/py4j/java_gateway.py", line 1132, in start
    self.socket.connect((self.address, self.port))
ConnectionRefusedError: [Errno 61] Connection refused
2024-06-09 00:31:27,626 - py4j.java_gateway - ERROR - An error occurred while trying to connect to the Java server (127.0.0.1:25333)
Traceback (most recent call last):
  File "/Users/leandrohoenen/PycharmProjects/pso-virtual-machine-resource-optimizer/.venv/lib/python3.12/site-packages/py4j/java_gateway.py", line 982, in _get_connection
    connection = self.deque.pop()
                 ^^^^^^^^^^^^^^^^
IndexError: pop from an empty deque

During handling of the above exception, another exception occurred:

Traceback (most recent call last):
  File "/Users/leandrohoenen/PycharmProjects/pso-virtual-machine-resource-optimizer/.venv/lib/python3.12/site-packages/py4j/java_gateway.py", line 1132, in start
    self.socket.connect((self.address, self.port))
ConnectionRefusedError: [Errno 61] Connection refused
2024-06-09 00:31:27,626 - py4j.java_gateway - ERROR - An error occurred while trying to connect to the Java server (127.0.0.1:25333)
Traceback (most recent call last):
  File "/Users/leandrohoenen/PycharmProjects/pso-virtual-machine-resource-optimizer/.venv/lib/python3.12/site-packages/py4j/java_gateway.py", line 982, in _get_connection
    connection = self.deque.pop()
                 ^^^^^^^^^^^^^^^^
IndexError: pop from an empty deque

During handling of the above exception, another exception occurred:

Traceback (most recent call last):
  File "/Users/leandrohoenen/PycharmProjects/pso-virtual-machine-resource-optimizer/.venv/lib/python3.12/site-packages/py4j/java_gateway.py", line 1132, in start
    self.socket.connect((self.address, self.port))
ConnectionRefusedError: [Errno 61] Connection refused
2024-06-09 00:31:27,626 - py4j.java_gateway - ERROR - An error occurred while trying to connect to the Java server (127.0.0.1:25333)
Traceback (most recent call last):
  File "/Users/leandrohoenen/PycharmProjects/pso-virtual-machine-resource-optimizer/.venv/lib/python3.12/site-packages/py4j/java_gateway.py", line 982, in _get_connection
    connection = self.deque.pop()
                 ^^^^^^^^^^^^^^^^
IndexError: pop from an empty deque

During handling of the above exception, another exception occurred:

Traceback (most recent call last):
  File "/Users/leandrohoenen/PycharmProjects/pso-virtual-machine-resource-optimizer/.venv/lib/python3.12/site-packages/py4j/java_gateway.py", line 1132, in start
    self.socket.connect((self.address, self.port))
ConnectionRefusedError: [Errno 61] Connection refused
2024-06-09 00:31:27,626 - py4j.java_gateway - ERROR - An error occurred while trying to connect to the Java server (127.0.0.1:25333)
Traceback (most recent call last):
  File "/Users/leandrohoenen/PycharmProjects/pso-virtual-machine-resource-optimizer/.venv/lib/python3.12/site-packages/py4j/java_gateway.py", line 982, in _get_connection
    connection = self.deque.pop()
                 ^^^^^^^^^^^^^^^^
IndexError: pop from an empty deque

During handling of the above exception, another exception occurred:

Traceback (most recent call last):
  File "/Users/leandrohoenen/PycharmProjects/pso-virtual-machine-resource-optimizer/.venv/lib/python3.12/site-packages/py4j/java_gateway.py", line 1132, in start
    self.socket.connect((self.address, self.port))
ConnectionRefusedError: [Errno 61] Connection refused
2024-06-09 00:31:27,627 - py4j.java_gateway - ERROR - An error occurred while trying to connect to the Java server (127.0.0.1:25333)
Traceback (most recent call last):
  File "/Users/leandrohoenen/PycharmProjects/pso-virtual-machine-resource-optimizer/.venv/lib/python3.12/site-packages/py4j/java_gateway.py", line 982, in _get_connection
    connection = self.deque.pop()
                 ^^^^^^^^^^^^^^^^
IndexError: pop from an empty deque

During handling of the above exception, another exception occurred:

Traceback (most recent call last):
  File "/Users/leandrohoenen/PycharmProjects/pso-virtual-machine-resource-optimizer/.venv/lib/python3.12/site-packages/py4j/java_gateway.py", line 1132, in start
    self.socket.connect((self.address, self.port))
ConnectionRefusedError: [Errno 61] Connection refused
2024-06-09 00:31:27,627 - py4j.java_gateway - ERROR - An error occurred while trying to connect to the Java server (127.0.0.1:25333)
Traceback (most recent call last):
  File "/Users/leandrohoenen/PycharmProjects/pso-virtual-machine-resource-optimizer/.venv/lib/python3.12/site-packages/py4j/java_gateway.py", line 982, in _get_connection
    connection = self.deque.pop()
                 ^^^^^^^^^^^^^^^^
IndexError: pop from an empty deque

During handling of the above exception, another exception occurred:

Traceback (most recent call last):
  File "/Users/leandrohoenen/PycharmProjects/pso-virtual-machine-resource-optimizer/.venv/lib/python3.12/site-packages/py4j/java_gateway.py", line 1132, in start
    self.socket.connect((self.address, self.port))
ConnectionRefusedError: [Errno 61] Connection refused
2024-06-09 00:31:27,627 - py4j.java_gateway - ERROR - An error occurred while trying to connect to the Java server (127.0.0.1:25333)
Traceback (most recent call last):
  File "/Users/leandrohoenen/PycharmProjects/pso-virtual-machine-resource-optimizer/.venv/lib/python3.12/site-packages/py4j/java_gateway.py", line 982, in _get_connection
    connection = self.deque.pop()
                 ^^^^^^^^^^^^^^^^
IndexError: pop from an empty deque

During handling of the above exception, another exception occurred:

Traceback (most recent call last):
  File "/Users/leandrohoenen/PycharmProjects/pso-virtual-machine-resource-optimizer/.venv/lib/python3.12/site-packages/py4j/java_gateway.py", line 1132, in start
    self.socket.connect((self.address, self.port))
ConnectionRefusedError: [Errno 61] Connection refused
2024-06-09 00:31:27,627 - py4j.java_gateway - ERROR - An error occurred while trying to connect to the Java server (127.0.0.1:25333)
Traceback (most recent call last):
  File "/Users/leandrohoenen/PycharmProjects/pso-virtual-machine-resource-optimizer/.venv/lib/python3.12/site-packages/py4j/java_gateway.py", line 982, in _get_connection
    connection = self.deque.pop()
                 ^^^^^^^^^^^^^^^^
IndexError: pop from an empty deque

During handling of the above exception, another exception occurred:

Traceback (most recent call last):
  File "/Users/leandrohoenen/PycharmProjects/pso-virtual-machine-resource-optimizer/.venv/lib/python3.12/site-packages/py4j/java_gateway.py", line 1132, in start
    self.socket.connect((self.address, self.port))
ConnectionRefusedError: [Errno 61] Connection refused
2024-06-09 00:31:27,627 - py4j.java_gateway - ERROR - An error occurred while trying to connect to the Java server (127.0.0.1:25333)
Traceback (most recent call last):
  File "/Users/leandrohoenen/PycharmProjects/pso-virtual-machine-resource-optimizer/.venv/lib/python3.12/site-packages/py4j/java_gateway.py", line 982, in _get_connection
    connection = self.deque.pop()
                 ^^^^^^^^^^^^^^^^
IndexError: pop from an empty deque

During handling of the above exception, another exception occurred:

Traceback (most recent call last):
  File "/Users/leandrohoenen/PycharmProjects/pso-virtual-machine-resource-optimizer/.venv/lib/python3.12/site-packages/py4j/java_gateway.py", line 1132, in start
    self.socket.connect((self.address, self.port))
ConnectionRefusedError: [Errno 61] Connection refused
2024-06-09 00:31:27,627 - py4j.java_gateway - ERROR - An error occurred while trying to connect to the Java server (127.0.0.1:25333)
Traceback (most recent call last):
  File "/Users/leandrohoenen/PycharmProjects/pso-virtual-machine-resource-optimizer/.venv/lib/python3.12/site-packages/py4j/java_gateway.py", line 982, in _get_connection
    connection = self.deque.pop()
                 ^^^^^^^^^^^^^^^^
IndexError: pop from an empty deque

During handling of the above exception, another exception occurred:

Traceback (most recent call last):
  File "/Users/leandrohoenen/PycharmProjects/pso-virtual-machine-resource-optimizer/.venv/lib/python3.12/site-packages/py4j/java_gateway.py", line 1132, in start
    self.socket.connect((self.address, self.port))
ConnectionRefusedError: [Errno 61] Connection refused
2024-06-09 00:31:27,628 - py4j.java_gateway - ERROR - An error occurred while trying to connect to the Java server (127.0.0.1:25333)
Traceback (most recent call last):
  File "/Users/leandrohoenen/PycharmProjects/pso-virtual-machine-resource-optimizer/.venv/lib/python3.12/site-packages/py4j/java_gateway.py", line 982, in _get_connection
    connection = self.deque.pop()
                 ^^^^^^^^^^^^^^^^
IndexError: pop from an empty deque

During handling of the above exception, another exception occurred:

Traceback (most recent call last):
  File "/Users/leandrohoenen/PycharmProjects/pso-virtual-machine-resource-optimizer/.venv/lib/python3.12/site-packages/py4j/java_gateway.py", line 1132, in start
    self.socket.connect((self.address, self.port))
ConnectionRefusedError: [Errno 61] Connection refused
2024-06-09 00:31:27,628 - py4j.java_gateway - ERROR - An error occurred while trying to connect to the Java server (127.0.0.1:25333)
Traceback (most recent call last):
  File "/Users/leandrohoenen/PycharmProjects/pso-virtual-machine-resource-optimizer/.venv/lib/python3.12/site-packages/py4j/java_gateway.py", line 982, in _get_connection
    connection = self.deque.pop()
                 ^^^^^^^^^^^^^^^^
IndexError: pop from an empty deque

During handling of the above exception, another exception occurred:

Traceback (most recent call last):
  File "/Users/leandrohoenen/PycharmProjects/pso-virtual-machine-resource-optimizer/.venv/lib/python3.12/site-packages/py4j/java_gateway.py", line 1132, in start
    self.socket.connect((self.address, self.port))
ConnectionRefusedError: [Errno 61] Connection refused
2024-06-09 00:31:27,628 - py4j.java_gateway - ERROR - An error occurred while trying to connect to the Java server (127.0.0.1:25333)
Traceback (most recent call last):
  File "/Users/leandrohoenen/PycharmProjects/pso-virtual-machine-resource-optimizer/.venv/lib/python3.12/site-packages/py4j/java_gateway.py", line 982, in _get_connection
    connection = self.deque.pop()
                 ^^^^^^^^^^^^^^^^
IndexError: pop from an empty deque

During handling of the above exception, another exception occurred:

Traceback (most recent call last):
  File "/Users/leandrohoenen/PycharmProjects/pso-virtual-machine-resource-optimizer/.venv/lib/python3.12/site-packages/py4j/java_gateway.py", line 1132, in start
    self.socket.connect((self.address, self.port))
ConnectionRefusedError: [Errno 61] Connection refused
2024-06-09 00:31:27,628 - py4j.java_gateway - ERROR - An error occurred while trying to connect to the Java server (127.0.0.1:25333)
Traceback (most recent call last):
  File "/Users/leandrohoenen/PycharmProjects/pso-virtual-machine-resource-optimizer/.venv/lib/python3.12/site-packages/py4j/java_gateway.py", line 982, in _get_connection
    connection = self.deque.pop()
                 ^^^^^^^^^^^^^^^^
IndexError: pop from an empty deque

During handling of the above exception, another exception occurred:

Traceback (most recent call last):
  File "/Users/leandrohoenen/PycharmProjects/pso-virtual-machine-resource-optimizer/.venv/lib/python3.12/site-packages/py4j/java_gateway.py", line 1132, in start
    self.socket.connect((self.address, self.port))
ConnectionRefusedError: [Errno 61] Connection refused
2024-06-09 00:31:27,628 - py4j.java_gateway - ERROR - An error occurred while trying to connect to the Java server (127.0.0.1:25333)
Traceback (most recent call last):
  File "/Users/leandrohoenen/PycharmProjects/pso-virtual-machine-resource-optimizer/.venv/lib/python3.12/site-packages/py4j/java_gateway.py", line 982, in _get_connection
    connection = self.deque.pop()
                 ^^^^^^^^^^^^^^^^
IndexError: pop from an empty deque

During handling of the above exception, another exception occurred:

Traceback (most recent call last):
  File "/Users/leandrohoenen/PycharmProjects/pso-virtual-machine-resource-optimizer/.venv/lib/python3.12/site-packages/py4j/java_gateway.py", line 1132, in start
    self.socket.connect((self.address, self.port))
ConnectionRefusedError: [Errno 61] Connection refused
2024-06-09 00:31:27,628 - py4j.java_gateway - ERROR - An error occurred while trying to connect to the Java server (127.0.0.1:25333)
Traceback (most recent call last):
  File "/Users/leandrohoenen/PycharmProjects/pso-virtual-machine-resource-optimizer/.venv/lib/python3.12/site-packages/py4j/java_gateway.py", line 982, in _get_connection
    connection = self.deque.pop()
                 ^^^^^^^^^^^^^^^^
IndexError: pop from an empty deque

During handling of the above exception, another exception occurred:

Traceback (most recent call last):
  File "/Users/leandrohoenen/PycharmProjects/pso-virtual-machine-resource-optimizer/.venv/lib/python3.12/site-packages/py4j/java_gateway.py", line 1132, in start
    self.socket.connect((self.address, self.port))
ConnectionRefusedError: [Errno 61] Connection refused
2024-06-09 00:31:27,629 - py4j.java_gateway - ERROR - An error occurred while trying to connect to the Java server (127.0.0.1:25333)
Traceback (most recent call last):
  File "/Users/leandrohoenen/PycharmProjects/pso-virtual-machine-resource-optimizer/.venv/lib/python3.12/site-packages/py4j/java_gateway.py", line 982, in _get_connection
    connection = self.deque.pop()
                 ^^^^^^^^^^^^^^^^
IndexError: pop from an empty deque

During handling of the above exception, another exception occurred:

Traceback (most recent call last):
  File "/Users/leandrohoenen/PycharmProjects/pso-virtual-machine-resource-optimizer/.venv/lib/python3.12/site-packages/py4j/java_gateway.py", line 1132, in start
    self.socket.connect((self.address, self.port))
ConnectionRefusedError: [Errno 61] Connection refused
2024-06-09 00:31:27,629 - py4j.java_gateway - ERROR - An error occurred while trying to connect to the Java server (127.0.0.1:25333)
Traceback (most recent call last):
  File "/Users/leandrohoenen/PycharmProjects/pso-virtual-machine-resource-optimizer/.venv/lib/python3.12/site-packages/py4j/java_gateway.py", line 982, in _get_connection
    connection = self.deque.pop()
                 ^^^^^^^^^^^^^^^^
IndexError: pop from an empty deque

During handling of the above exception, another exception occurred:

Traceback (most recent call last):
  File "/Users/leandrohoenen/PycharmProjects/pso-virtual-machine-resource-optimizer/.venv/lib/python3.12/site-packages/py4j/java_gateway.py", line 1132, in start
    self.socket.connect((self.address, self.port))
ConnectionRefusedError: [Errno 61] Connection refused
2024-06-09 00:31:27,629 - py4j.java_gateway - ERROR - An error occurred while trying to connect to the Java server (127.0.0.1:25333)
Traceback (most recent call last):
  File "/Users/leandrohoenen/PycharmProjects/pso-virtual-machine-resource-optimizer/.venv/lib/python3.12/site-packages/py4j/java_gateway.py", line 982, in _get_connection
    connection = self.deque.pop()
                 ^^^^^^^^^^^^^^^^
IndexError: pop from an empty deque

During handling of the above exception, another exception occurred:

Traceback (most recent call last):
  File "/Users/leandrohoenen/PycharmProjects/pso-virtual-machine-resource-optimizer/.venv/lib/python3.12/site-packages/py4j/java_gateway.py", line 1132, in start
    self.socket.connect((self.address, self.port))
ConnectionRefusedError: [Errno 61] Connection refused
2024-06-09 00:31:27,629 - py4j.java_gateway - ERROR - An error occurred while trying to connect to the Java server (127.0.0.1:25333)
Traceback (most recent call last):
  File "/Users/leandrohoenen/PycharmProjects/pso-virtual-machine-resource-optimizer/.venv/lib/python3.12/site-packages/py4j/java_gateway.py", line 982, in _get_connection
    connection = self.deque.pop()
                 ^^^^^^^^^^^^^^^^
IndexError: pop from an empty deque

During handling of the above exception, another exception occurred:

Traceback (most recent call last):
  File "/Users/leandrohoenen/PycharmProjects/pso-virtual-machine-resource-optimizer/.venv/lib/python3.12/site-packages/py4j/java_gateway.py", line 1132, in start
    self.socket.connect((self.address, self.port))
ConnectionRefusedError: [Errno 61] Connection refused
2024-06-09 00:31:27,630 - py4j.java_gateway - ERROR - An error occurred while trying to connect to the Java server (127.0.0.1:25333)
Traceback (most recent call last):
  File "/Users/leandrohoenen/PycharmProjects/pso-virtual-machine-resource-optimizer/.venv/lib/python3.12/site-packages/py4j/java_gateway.py", line 982, in _get_connection
    connection = self.deque.pop()
                 ^^^^^^^^^^^^^^^^
IndexError: pop from an empty deque

During handling of the above exception, another exception occurred:

Traceback (most recent call last):
  File "/Users/leandrohoenen/PycharmProjects/pso-virtual-machine-resource-optimizer/.venv/lib/python3.12/site-packages/py4j/java_gateway.py", line 1132, in start
    self.socket.connect((self.address, self.port))
ConnectionRefusedError: [Errno 61] Connection refused
2024-06-09 00:31:27,630 - py4j.java_gateway - ERROR - An error occurred while trying to connect to the Java server (127.0.0.1:25333)
Traceback (most recent call last):
  File "/Users/leandrohoenen/PycharmProjects/pso-virtual-machine-resource-optimizer/.venv/lib/python3.12/site-packages/py4j/java_gateway.py", line 982, in _get_connection
    connection = self.deque.pop()
                 ^^^^^^^^^^^^^^^^
IndexError: pop from an empty deque

During handling of the above exception, another exception occurred:

Traceback (most recent call last):
  File "/Users/leandrohoenen/PycharmProjects/pso-virtual-machine-resource-optimizer/.venv/lib/python3.12/site-packages/py4j/java_gateway.py", line 1132, in start
    self.socket.connect((self.address, self.port))
ConnectionRefusedError: [Errno 61] Connection refused
2024-06-09 00:31:27,630 - py4j.java_gateway - ERROR - An error occurred while trying to connect to the Java server (127.0.0.1:25333)
Traceback (most recent call last):
  File "/Users/leandrohoenen/PycharmProjects/pso-virtual-machine-resource-optimizer/.venv/lib/python3.12/site-packages/py4j/java_gateway.py", line 982, in _get_connection
    connection = self.deque.pop()
                 ^^^^^^^^^^^^^^^^
IndexError: pop from an empty deque

During handling of the above exception, another exception occurred:

Traceback (most recent call last):
  File "/Users/leandrohoenen/PycharmProjects/pso-virtual-machine-resource-optimizer/.venv/lib/python3.12/site-packages/py4j/java_gateway.py", line 1132, in start
    self.socket.connect((self.address, self.port))
ConnectionRefusedError: [Errno 61] Connection refused
2024-06-09 00:31:27,630 - py4j.java_gateway - ERROR - An error occurred while trying to connect to the Java server (127.0.0.1:25333)
Traceback (most recent call last):
  File "/Users/leandrohoenen/PycharmProjects/pso-virtual-machine-resource-optimizer/.venv/lib/python3.12/site-packages/py4j/java_gateway.py", line 982, in _get_connection
    connection = self.deque.pop()
                 ^^^^^^^^^^^^^^^^
IndexError: pop from an empty deque

During handling of the above exception, another exception occurred:

Traceback (most recent call last):
  File "/Users/leandrohoenen/PycharmProjects/pso-virtual-machine-resource-optimizer/.venv/lib/python3.12/site-packages/py4j/java_gateway.py", line 1132, in start
    self.socket.connect((self.address, self.port))
ConnectionRefusedError: [Errno 61] Connection refused
2024-06-09 00:31:27,630 - py4j.java_gateway - ERROR - An error occurred while trying to connect to the Java server (127.0.0.1:25333)
Traceback (most recent call last):
  File "/Users/leandrohoenen/PycharmProjects/pso-virtual-machine-resource-optimizer/.venv/lib/python3.12/site-packages/py4j/java_gateway.py", line 982, in _get_connection
    connection = self.deque.pop()
                 ^^^^^^^^^^^^^^^^
IndexError: pop from an empty deque

During handling of the above exception, another exception occurred:

Traceback (most recent call last):
  File "/Users/leandrohoenen/PycharmProjects/pso-virtual-machine-resource-optimizer/.venv/lib/python3.12/site-packages/py4j/java_gateway.py", line 1132, in start
    self.socket.connect((self.address, self.port))
ConnectionRefusedError: [Errno 61] Connection refused
2024-06-09 00:31:27,631 - py4j.java_gateway - ERROR - An error occurred while trying to connect to the Java server (127.0.0.1:25333)
Traceback (most recent call last):
  File "/Users/leandrohoenen/PycharmProjects/pso-virtual-machine-resource-optimizer/.venv/lib/python3.12/site-packages/py4j/java_gateway.py", line 982, in _get_connection
    connection = self.deque.pop()
                 ^^^^^^^^^^^^^^^^
IndexError: pop from an empty deque

During handling of the above exception, another exception occurred:

Traceback (most recent call last):
  File "/Users/leandrohoenen/PycharmProjects/pso-virtual-machine-resource-optimizer/.venv/lib/python3.12/site-packages/py4j/java_gateway.py", line 1132, in start
    self.socket.connect((self.address, self.port))
ConnectionRefusedError: [Errno 61] Connection refused
2024-06-09 00:31:27,651 - py4j.java_gateway - ERROR - An error occurred while trying to connect to the Java server (127.0.0.1:25333)
Traceback (most recent call last):
  File "/Users/leandrohoenen/PycharmProjects/pso-virtual-machine-resource-optimizer/.venv/lib/python3.12/site-packages/py4j/java_gateway.py", line 982, in _get_connection
    connection = self.deque.pop()
                 ^^^^^^^^^^^^^^^^
IndexError: pop from an empty deque

During handling of the above exception, another exception occurred:

Traceback (most recent call last):
  File "/Users/leandrohoenen/PycharmProjects/pso-virtual-machine-resource-optimizer/.venv/lib/python3.12/site-packages/py4j/java_gateway.py", line 1132, in start
    self.socket.connect((self.address, self.port))
ConnectionRefusedError: [Errno 61] Connection refused
2024-06-09 00:31:38,030 - pyswarms.single.global_best - INFO - Optimize for 400 iters with {'c1': 0.5, 'c2': 0.3, 'w': 0.9}
2024-06-09 00:31:41,870 - pyswarms.single.global_best - INFO - Optimization finished | best cost: 686.7766666666666, best pos: [ 9.28459205 11.03382023]
2024-06-09 00:32:02,734 - pyswarms.single.global_best - INFO - Optimize for 400 iters with {'c1': 0.5, 'c2': 0.3, 'w': 0.9}
2024-06-09 00:32:10,604 - root - ERROR - KeyboardInterrupt while sending command.
Traceback (most recent call last):
  File "/Users/leandrohoenen/PycharmProjects/pso-virtual-machine-resource-optimizer/.venv/lib/python3.12/site-packages/py4j/java_gateway.py", line 1038, in send_command
    response = connection.send_command(command)
               ^^^^^^^^^^^^^^^^^^^^^^^^^^^^^^^^
  File "/Users/leandrohoenen/PycharmProjects/pso-virtual-machine-resource-optimizer/.venv/lib/python3.12/site-packages/py4j/java_gateway.py", line 1217, in send_command
    answer = smart_decode(self.stream.readline()[:-1])
                          ^^^^^^^^^^^^^^^^^^^^^^
  File "/Library/Frameworks/Python.framework/Versions/3.12/lib/python3.12/socket.py", line 707, in readinto
    return self._sock.recv_into(b)
           ^^^^^^^^^^^^^^^^^^^^^^^
KeyboardInterrupt
2024-06-09 00:32:30,986 - pyswarms.single.global_best - INFO - Optimize for 400 iters with {'c1': 0.5, 'c2': 0.3, 'w': 0.9}
2024-06-09 00:33:21,316 - py4j.java_gateway - INFO - Error while receiving.
Traceback (most recent call last):
  File "/Users/leandrohoenen/PycharmProjects/pso-virtual-machine-resource-optimizer/.venv/lib/python3.12/site-packages/py4j/java_gateway.py", line 1224, in send_command
    raise Py4JNetworkError("Answer from Java side is empty")
py4j.protocol.Py4JNetworkError: Answer from Java side is empty
2024-06-09 00:33:21,320 - root - ERROR - Exception while sending command.
Traceback (most recent call last):
  File "/Users/leandrohoenen/PycharmProjects/pso-virtual-machine-resource-optimizer/.venv/lib/python3.12/site-packages/py4j/java_gateway.py", line 1224, in send_command
    raise Py4JNetworkError("Answer from Java side is empty")
py4j.protocol.Py4JNetworkError: Answer from Java side is empty

During handling of the above exception, another exception occurred:

Traceback (most recent call last):
  File "/Users/leandrohoenen/PycharmProjects/pso-virtual-machine-resource-optimizer/.venv/lib/python3.12/site-packages/py4j/java_gateway.py", line 1038, in send_command
    response = connection.send_command(command)
               ^^^^^^^^^^^^^^^^^^^^^^^^^^^^^^^^
  File "/Users/leandrohoenen/PycharmProjects/pso-virtual-machine-resource-optimizer/.venv/lib/python3.12/site-packages/py4j/java_gateway.py", line 1228, in send_command
    raise Py4JNetworkError(
py4j.protocol.Py4JNetworkError: Error while receiving
2024-06-09 00:33:21,323 - py4j.java_gateway - ERROR - An error occurred while trying to connect to the Java server (127.0.0.1:25333)
Traceback (most recent call last):
  File "/Users/leandrohoenen/PycharmProjects/pso-virtual-machine-resource-optimizer/.venv/lib/python3.12/site-packages/py4j/java_gateway.py", line 982, in _get_connection
    connection = self.deque.pop()
                 ^^^^^^^^^^^^^^^^
IndexError: pop from an empty deque

During handling of the above exception, another exception occurred:

Traceback (most recent call last):
  File "/Users/leandrohoenen/PycharmProjects/pso-virtual-machine-resource-optimizer/.venv/lib/python3.12/site-packages/py4j/java_gateway.py", line 1132, in start
    self.socket.connect((self.address, self.port))
ConnectionRefusedError: [Errno 61] Connection refused
2024-06-09 00:33:21,324 - py4j.java_gateway - ERROR - An error occurred while trying to connect to the Java server (127.0.0.1:25333)
Traceback (most recent call last):
  File "/Users/leandrohoenen/PycharmProjects/pso-virtual-machine-resource-optimizer/.venv/lib/python3.12/site-packages/py4j/java_gateway.py", line 982, in _get_connection
    connection = self.deque.pop()
                 ^^^^^^^^^^^^^^^^
IndexError: pop from an empty deque

During handling of the above exception, another exception occurred:

Traceback (most recent call last):
  File "/Users/leandrohoenen/PycharmProjects/pso-virtual-machine-resource-optimizer/.venv/lib/python3.12/site-packages/py4j/java_gateway.py", line 1132, in start
    self.socket.connect((self.address, self.port))
ConnectionRefusedError: [Errno 61] Connection refused
2024-06-09 00:33:21,325 - py4j.java_gateway - ERROR - An error occurred while trying to connect to the Java server (127.0.0.1:25333)
Traceback (most recent call last):
  File "/Users/leandrohoenen/PycharmProjects/pso-virtual-machine-resource-optimizer/.venv/lib/python3.12/site-packages/py4j/java_gateway.py", line 982, in _get_connection
    connection = self.deque.pop()
                 ^^^^^^^^^^^^^^^^
IndexError: pop from an empty deque

During handling of the above exception, another exception occurred:

Traceback (most recent call last):
  File "/Users/leandrohoenen/PycharmProjects/pso-virtual-machine-resource-optimizer/.venv/lib/python3.12/site-packages/py4j/java_gateway.py", line 1132, in start
    self.socket.connect((self.address, self.port))
ConnectionRefusedError: [Errno 61] Connection refused
2024-06-09 00:33:21,325 - py4j.java_gateway - ERROR - An error occurred while trying to connect to the Java server (127.0.0.1:25333)
Traceback (most recent call last):
  File "/Users/leandrohoenen/PycharmProjects/pso-virtual-machine-resource-optimizer/.venv/lib/python3.12/site-packages/py4j/java_gateway.py", line 982, in _get_connection
    connection = self.deque.pop()
                 ^^^^^^^^^^^^^^^^
IndexError: pop from an empty deque

During handling of the above exception, another exception occurred:

Traceback (most recent call last):
  File "/Users/leandrohoenen/PycharmProjects/pso-virtual-machine-resource-optimizer/.venv/lib/python3.12/site-packages/py4j/java_gateway.py", line 1132, in start
    self.socket.connect((self.address, self.port))
ConnectionRefusedError: [Errno 61] Connection refused
2024-06-09 00:33:21,326 - py4j.java_gateway - ERROR - An error occurred while trying to connect to the Java server (127.0.0.1:25333)
Traceback (most recent call last):
  File "/Users/leandrohoenen/PycharmProjects/pso-virtual-machine-resource-optimizer/.venv/lib/python3.12/site-packages/py4j/java_gateway.py", line 982, in _get_connection
    connection = self.deque.pop()
                 ^^^^^^^^^^^^^^^^
IndexError: pop from an empty deque

During handling of the above exception, another exception occurred:

Traceback (most recent call last):
  File "/Users/leandrohoenen/PycharmProjects/pso-virtual-machine-resource-optimizer/.venv/lib/python3.12/site-packages/py4j/java_gateway.py", line 1132, in start
    self.socket.connect((self.address, self.port))
ConnectionRefusedError: [Errno 61] Connection refused
2024-06-09 00:33:21,327 - py4j.java_gateway - ERROR - An error occurred while trying to connect to the Java server (127.0.0.1:25333)
Traceback (most recent call last):
  File "/Users/leandrohoenen/PycharmProjects/pso-virtual-machine-resource-optimizer/.venv/lib/python3.12/site-packages/py4j/java_gateway.py", line 982, in _get_connection
    connection = self.deque.pop()
                 ^^^^^^^^^^^^^^^^
IndexError: pop from an empty deque

During handling of the above exception, another exception occurred:

Traceback (most recent call last):
  File "/Users/leandrohoenen/PycharmProjects/pso-virtual-machine-resource-optimizer/.venv/lib/python3.12/site-packages/py4j/java_gateway.py", line 1132, in start
    self.socket.connect((self.address, self.port))
ConnectionRefusedError: [Errno 61] Connection refused
2024-06-09 00:33:21,328 - py4j.java_gateway - ERROR - An error occurred while trying to connect to the Java server (127.0.0.1:25333)
Traceback (most recent call last):
  File "/Users/leandrohoenen/PycharmProjects/pso-virtual-machine-resource-optimizer/.venv/lib/python3.12/site-packages/py4j/java_gateway.py", line 982, in _get_connection
    connection = self.deque.pop()
                 ^^^^^^^^^^^^^^^^
IndexError: pop from an empty deque

During handling of the above exception, another exception occurred:

Traceback (most recent call last):
  File "/Users/leandrohoenen/PycharmProjects/pso-virtual-machine-resource-optimizer/.venv/lib/python3.12/site-packages/py4j/java_gateway.py", line 1132, in start
    self.socket.connect((self.address, self.port))
ConnectionRefusedError: [Errno 61] Connection refused
2024-06-09 00:33:21,329 - py4j.java_gateway - ERROR - An error occurred while trying to connect to the Java server (127.0.0.1:25333)
Traceback (most recent call last):
  File "/Users/leandrohoenen/PycharmProjects/pso-virtual-machine-resource-optimizer/.venv/lib/python3.12/site-packages/py4j/java_gateway.py", line 982, in _get_connection
    connection = self.deque.pop()
                 ^^^^^^^^^^^^^^^^
IndexError: pop from an empty deque

During handling of the above exception, another exception occurred:

Traceback (most recent call last):
  File "/Users/leandrohoenen/PycharmProjects/pso-virtual-machine-resource-optimizer/.venv/lib/python3.12/site-packages/py4j/java_gateway.py", line 1132, in start
    self.socket.connect((self.address, self.port))
ConnectionRefusedError: [Errno 61] Connection refused
2024-06-09 00:33:21,330 - py4j.java_gateway - ERROR - An error occurred while trying to connect to the Java server (127.0.0.1:25333)
Traceback (most recent call last):
  File "/Users/leandrohoenen/PycharmProjects/pso-virtual-machine-resource-optimizer/.venv/lib/python3.12/site-packages/py4j/java_gateway.py", line 982, in _get_connection
    connection = self.deque.pop()
                 ^^^^^^^^^^^^^^^^
IndexError: pop from an empty deque

During handling of the above exception, another exception occurred:

Traceback (most recent call last):
  File "/Users/leandrohoenen/PycharmProjects/pso-virtual-machine-resource-optimizer/.venv/lib/python3.12/site-packages/py4j/java_gateway.py", line 1132, in start
    self.socket.connect((self.address, self.port))
ConnectionRefusedError: [Errno 61] Connection refused
2024-06-09 00:33:21,331 - py4j.java_gateway - ERROR - An error occurred while trying to connect to the Java server (127.0.0.1:25333)
Traceback (most recent call last):
  File "/Users/leandrohoenen/PycharmProjects/pso-virtual-machine-resource-optimizer/.venv/lib/python3.12/site-packages/py4j/java_gateway.py", line 982, in _get_connection
    connection = self.deque.pop()
                 ^^^^^^^^^^^^^^^^
IndexError: pop from an empty deque

During handling of the above exception, another exception occurred:

Traceback (most recent call last):
  File "/Users/leandrohoenen/PycharmProjects/pso-virtual-machine-resource-optimizer/.venv/lib/python3.12/site-packages/py4j/java_gateway.py", line 1132, in start
    self.socket.connect((self.address, self.port))
ConnectionRefusedError: [Errno 61] Connection refused
2024-06-09 00:33:21,332 - py4j.java_gateway - ERROR - An error occurred while trying to connect to the Java server (127.0.0.1:25333)
Traceback (most recent call last):
  File "/Users/leandrohoenen/PycharmProjects/pso-virtual-machine-resource-optimizer/.venv/lib/python3.12/site-packages/py4j/java_gateway.py", line 982, in _get_connection
    connection = self.deque.pop()
                 ^^^^^^^^^^^^^^^^
IndexError: pop from an empty deque

During handling of the above exception, another exception occurred:

Traceback (most recent call last):
  File "/Users/leandrohoenen/PycharmProjects/pso-virtual-machine-resource-optimizer/.venv/lib/python3.12/site-packages/py4j/java_gateway.py", line 1132, in start
    self.socket.connect((self.address, self.port))
ConnectionRefusedError: [Errno 61] Connection refused
2024-06-09 00:33:21,333 - py4j.java_gateway - ERROR - An error occurred while trying to connect to the Java server (127.0.0.1:25333)
Traceback (most recent call last):
  File "/Users/leandrohoenen/PycharmProjects/pso-virtual-machine-resource-optimizer/.venv/lib/python3.12/site-packages/py4j/java_gateway.py", line 982, in _get_connection
    connection = self.deque.pop()
                 ^^^^^^^^^^^^^^^^
IndexError: pop from an empty deque

During handling of the above exception, another exception occurred:

Traceback (most recent call last):
  File "/Users/leandrohoenen/PycharmProjects/pso-virtual-machine-resource-optimizer/.venv/lib/python3.12/site-packages/py4j/java_gateway.py", line 1132, in start
    self.socket.connect((self.address, self.port))
ConnectionRefusedError: [Errno 61] Connection refused
2024-06-09 00:33:21,333 - py4j.java_gateway - ERROR - An error occurred while trying to connect to the Java server (127.0.0.1:25333)
Traceback (most recent call last):
  File "/Users/leandrohoenen/PycharmProjects/pso-virtual-machine-resource-optimizer/.venv/lib/python3.12/site-packages/py4j/java_gateway.py", line 982, in _get_connection
    connection = self.deque.pop()
                 ^^^^^^^^^^^^^^^^
IndexError: pop from an empty deque

During handling of the above exception, another exception occurred:

Traceback (most recent call last):
  File "/Users/leandrohoenen/PycharmProjects/pso-virtual-machine-resource-optimizer/.venv/lib/python3.12/site-packages/py4j/java_gateway.py", line 1132, in start
    self.socket.connect((self.address, self.port))
ConnectionRefusedError: [Errno 61] Connection refused
2024-06-09 00:33:21,334 - py4j.java_gateway - ERROR - An error occurred while trying to connect to the Java server (127.0.0.1:25333)
Traceback (most recent call last):
  File "/Users/leandrohoenen/PycharmProjects/pso-virtual-machine-resource-optimizer/.venv/lib/python3.12/site-packages/py4j/java_gateway.py", line 982, in _get_connection
    connection = self.deque.pop()
                 ^^^^^^^^^^^^^^^^
IndexError: pop from an empty deque

During handling of the above exception, another exception occurred:

Traceback (most recent call last):
  File "/Users/leandrohoenen/PycharmProjects/pso-virtual-machine-resource-optimizer/.venv/lib/python3.12/site-packages/py4j/java_gateway.py", line 1132, in start
    self.socket.connect((self.address, self.port))
ConnectionRefusedError: [Errno 61] Connection refused
2024-06-09 00:33:21,334 - py4j.java_gateway - ERROR - An error occurred while trying to connect to the Java server (127.0.0.1:25333)
Traceback (most recent call last):
  File "/Users/leandrohoenen/PycharmProjects/pso-virtual-machine-resource-optimizer/.venv/lib/python3.12/site-packages/py4j/java_gateway.py", line 982, in _get_connection
    connection = self.deque.pop()
                 ^^^^^^^^^^^^^^^^
IndexError: pop from an empty deque

During handling of the above exception, another exception occurred:

Traceback (most recent call last):
  File "/Users/leandrohoenen/PycharmProjects/pso-virtual-machine-resource-optimizer/.venv/lib/python3.12/site-packages/py4j/java_gateway.py", line 1132, in start
    self.socket.connect((self.address, self.port))
ConnectionRefusedError: [Errno 61] Connection refused
2024-06-09 00:33:21,335 - py4j.java_gateway - ERROR - An error occurred while trying to connect to the Java server (127.0.0.1:25333)
Traceback (most recent call last):
  File "/Users/leandrohoenen/PycharmProjects/pso-virtual-machine-resource-optimizer/.venv/lib/python3.12/site-packages/py4j/java_gateway.py", line 982, in _get_connection
    connection = self.deque.pop()
                 ^^^^^^^^^^^^^^^^
IndexError: pop from an empty deque

During handling of the above exception, another exception occurred:

Traceback (most recent call last):
  File "/Users/leandrohoenen/PycharmProjects/pso-virtual-machine-resource-optimizer/.venv/lib/python3.12/site-packages/py4j/java_gateway.py", line 1132, in start
    self.socket.connect((self.address, self.port))
ConnectionRefusedError: [Errno 61] Connection refused
2024-06-09 00:33:21,335 - py4j.java_gateway - ERROR - An error occurred while trying to connect to the Java server (127.0.0.1:25333)
Traceback (most recent call last):
  File "/Users/leandrohoenen/PycharmProjects/pso-virtual-machine-resource-optimizer/.venv/lib/python3.12/site-packages/py4j/java_gateway.py", line 982, in _get_connection
    connection = self.deque.pop()
                 ^^^^^^^^^^^^^^^^
IndexError: pop from an empty deque

During handling of the above exception, another exception occurred:

Traceback (most recent call last):
  File "/Users/leandrohoenen/PycharmProjects/pso-virtual-machine-resource-optimizer/.venv/lib/python3.12/site-packages/py4j/java_gateway.py", line 1132, in start
    self.socket.connect((self.address, self.port))
ConnectionRefusedError: [Errno 61] Connection refused
2024-06-09 00:33:21,336 - py4j.java_gateway - ERROR - An error occurred while trying to connect to the Java server (127.0.0.1:25333)
Traceback (most recent call last):
  File "/Users/leandrohoenen/PycharmProjects/pso-virtual-machine-resource-optimizer/.venv/lib/python3.12/site-packages/py4j/java_gateway.py", line 982, in _get_connection
    connection = self.deque.pop()
                 ^^^^^^^^^^^^^^^^
IndexError: pop from an empty deque

During handling of the above exception, another exception occurred:

Traceback (most recent call last):
  File "/Users/leandrohoenen/PycharmProjects/pso-virtual-machine-resource-optimizer/.venv/lib/python3.12/site-packages/py4j/java_gateway.py", line 1132, in start
    self.socket.connect((self.address, self.port))
ConnectionRefusedError: [Errno 61] Connection refused
2024-06-09 00:33:21,336 - py4j.java_gateway - ERROR - An error occurred while trying to connect to the Java server (127.0.0.1:25333)
Traceback (most recent call last):
  File "/Users/leandrohoenen/PycharmProjects/pso-virtual-machine-resource-optimizer/.venv/lib/python3.12/site-packages/py4j/java_gateway.py", line 982, in _get_connection
    connection = self.deque.pop()
                 ^^^^^^^^^^^^^^^^
IndexError: pop from an empty deque

During handling of the above exception, another exception occurred:

Traceback (most recent call last):
  File "/Users/leandrohoenen/PycharmProjects/pso-virtual-machine-resource-optimizer/.venv/lib/python3.12/site-packages/py4j/java_gateway.py", line 1132, in start
    self.socket.connect((self.address, self.port))
ConnectionRefusedError: [Errno 61] Connection refused
2024-06-09 00:33:21,337 - py4j.java_gateway - ERROR - An error occurred while trying to connect to the Java server (127.0.0.1:25333)
Traceback (most recent call last):
  File "/Users/leandrohoenen/PycharmProjects/pso-virtual-machine-resource-optimizer/.venv/lib/python3.12/site-packages/py4j/java_gateway.py", line 982, in _get_connection
    connection = self.deque.pop()
                 ^^^^^^^^^^^^^^^^
IndexError: pop from an empty deque

During handling of the above exception, another exception occurred:

Traceback (most recent call last):
  File "/Users/leandrohoenen/PycharmProjects/pso-virtual-machine-resource-optimizer/.venv/lib/python3.12/site-packages/py4j/java_gateway.py", line 1132, in start
    self.socket.connect((self.address, self.port))
ConnectionRefusedError: [Errno 61] Connection refused
2024-06-09 00:33:21,337 - py4j.java_gateway - ERROR - An error occurred while trying to connect to the Java server (127.0.0.1:25333)
Traceback (most recent call last):
  File "/Users/leandrohoenen/PycharmProjects/pso-virtual-machine-resource-optimizer/.venv/lib/python3.12/site-packages/py4j/java_gateway.py", line 982, in _get_connection
    connection = self.deque.pop()
                 ^^^^^^^^^^^^^^^^
IndexError: pop from an empty deque

During handling of the above exception, another exception occurred:

Traceback (most recent call last):
  File "/Users/leandrohoenen/PycharmProjects/pso-virtual-machine-resource-optimizer/.venv/lib/python3.12/site-packages/py4j/java_gateway.py", line 1132, in start
    self.socket.connect((self.address, self.port))
ConnectionRefusedError: [Errno 61] Connection refused
2024-06-09 00:33:21,337 - py4j.java_gateway - ERROR - An error occurred while trying to connect to the Java server (127.0.0.1:25333)
Traceback (most recent call last):
  File "/Users/leandrohoenen/PycharmProjects/pso-virtual-machine-resource-optimizer/.venv/lib/python3.12/site-packages/py4j/java_gateway.py", line 982, in _get_connection
    connection = self.deque.pop()
                 ^^^^^^^^^^^^^^^^
IndexError: pop from an empty deque

During handling of the above exception, another exception occurred:

Traceback (most recent call last):
  File "/Users/leandrohoenen/PycharmProjects/pso-virtual-machine-resource-optimizer/.venv/lib/python3.12/site-packages/py4j/java_gateway.py", line 1132, in start
    self.socket.connect((self.address, self.port))
ConnectionRefusedError: [Errno 61] Connection refused
2024-06-09 00:33:21,338 - py4j.java_gateway - ERROR - An error occurred while trying to connect to the Java server (127.0.0.1:25333)
Traceback (most recent call last):
  File "/Users/leandrohoenen/PycharmProjects/pso-virtual-machine-resource-optimizer/.venv/lib/python3.12/site-packages/py4j/java_gateway.py", line 982, in _get_connection
    connection = self.deque.pop()
                 ^^^^^^^^^^^^^^^^
IndexError: pop from an empty deque

During handling of the above exception, another exception occurred:

Traceback (most recent call last):
  File "/Users/leandrohoenen/PycharmProjects/pso-virtual-machine-resource-optimizer/.venv/lib/python3.12/site-packages/py4j/java_gateway.py", line 1132, in start
    self.socket.connect((self.address, self.port))
ConnectionRefusedError: [Errno 61] Connection refused
2024-06-09 00:33:21,338 - py4j.java_gateway - ERROR - An error occurred while trying to connect to the Java server (127.0.0.1:25333)
Traceback (most recent call last):
  File "/Users/leandrohoenen/PycharmProjects/pso-virtual-machine-resource-optimizer/.venv/lib/python3.12/site-packages/py4j/java_gateway.py", line 982, in _get_connection
    connection = self.deque.pop()
                 ^^^^^^^^^^^^^^^^
IndexError: pop from an empty deque

During handling of the above exception, another exception occurred:

Traceback (most recent call last):
  File "/Users/leandrohoenen/PycharmProjects/pso-virtual-machine-resource-optimizer/.venv/lib/python3.12/site-packages/py4j/java_gateway.py", line 1132, in start
    self.socket.connect((self.address, self.port))
ConnectionRefusedError: [Errno 61] Connection refused
2024-06-09 00:33:21,339 - py4j.java_gateway - ERROR - An error occurred while trying to connect to the Java server (127.0.0.1:25333)
Traceback (most recent call last):
  File "/Users/leandrohoenen/PycharmProjects/pso-virtual-machine-resource-optimizer/.venv/lib/python3.12/site-packages/py4j/java_gateway.py", line 982, in _get_connection
    connection = self.deque.pop()
                 ^^^^^^^^^^^^^^^^
IndexError: pop from an empty deque

During handling of the above exception, another exception occurred:

Traceback (most recent call last):
  File "/Users/leandrohoenen/PycharmProjects/pso-virtual-machine-resource-optimizer/.venv/lib/python3.12/site-packages/py4j/java_gateway.py", line 1132, in start
    self.socket.connect((self.address, self.port))
ConnectionRefusedError: [Errno 61] Connection refused
2024-06-09 00:33:21,339 - py4j.java_gateway - ERROR - An error occurred while trying to connect to the Java server (127.0.0.1:25333)
Traceback (most recent call last):
  File "/Users/leandrohoenen/PycharmProjects/pso-virtual-machine-resource-optimizer/.venv/lib/python3.12/site-packages/py4j/java_gateway.py", line 982, in _get_connection
    connection = self.deque.pop()
                 ^^^^^^^^^^^^^^^^
IndexError: pop from an empty deque

During handling of the above exception, another exception occurred:

Traceback (most recent call last):
  File "/Users/leandrohoenen/PycharmProjects/pso-virtual-machine-resource-optimizer/.venv/lib/python3.12/site-packages/py4j/java_gateway.py", line 1132, in start
    self.socket.connect((self.address, self.port))
ConnectionRefusedError: [Errno 61] Connection refused
2024-06-09 00:33:21,340 - py4j.java_gateway - ERROR - An error occurred while trying to connect to the Java server (127.0.0.1:25333)
Traceback (most recent call last):
  File "/Users/leandrohoenen/PycharmProjects/pso-virtual-machine-resource-optimizer/.venv/lib/python3.12/site-packages/py4j/java_gateway.py", line 982, in _get_connection
    connection = self.deque.pop()
                 ^^^^^^^^^^^^^^^^
IndexError: pop from an empty deque

During handling of the above exception, another exception occurred:

Traceback (most recent call last):
  File "/Users/leandrohoenen/PycharmProjects/pso-virtual-machine-resource-optimizer/.venv/lib/python3.12/site-packages/py4j/java_gateway.py", line 1132, in start
    self.socket.connect((self.address, self.port))
ConnectionRefusedError: [Errno 61] Connection refused
2024-06-09 00:33:21,340 - py4j.java_gateway - ERROR - An error occurred while trying to connect to the Java server (127.0.0.1:25333)
Traceback (most recent call last):
  File "/Users/leandrohoenen/PycharmProjects/pso-virtual-machine-resource-optimizer/.venv/lib/python3.12/site-packages/py4j/java_gateway.py", line 982, in _get_connection
    connection = self.deque.pop()
                 ^^^^^^^^^^^^^^^^
IndexError: pop from an empty deque

During handling of the above exception, another exception occurred:

Traceback (most recent call last):
  File "/Users/leandrohoenen/PycharmProjects/pso-virtual-machine-resource-optimizer/.venv/lib/python3.12/site-packages/py4j/java_gateway.py", line 1132, in start
    self.socket.connect((self.address, self.port))
ConnectionRefusedError: [Errno 61] Connection refused
2024-06-09 00:33:21,341 - py4j.java_gateway - ERROR - An error occurred while trying to connect to the Java server (127.0.0.1:25333)
Traceback (most recent call last):
  File "/Users/leandrohoenen/PycharmProjects/pso-virtual-machine-resource-optimizer/.venv/lib/python3.12/site-packages/py4j/java_gateway.py", line 982, in _get_connection
    connection = self.deque.pop()
                 ^^^^^^^^^^^^^^^^
IndexError: pop from an empty deque

During handling of the above exception, another exception occurred:

Traceback (most recent call last):
  File "/Users/leandrohoenen/PycharmProjects/pso-virtual-machine-resource-optimizer/.venv/lib/python3.12/site-packages/py4j/java_gateway.py", line 1132, in start
    self.socket.connect((self.address, self.port))
ConnectionRefusedError: [Errno 61] Connection refused
2024-06-09 00:33:21,368 - py4j.java_gateway - ERROR - An error occurred while trying to connect to the Java server (127.0.0.1:25333)
Traceback (most recent call last):
  File "/Users/leandrohoenen/PycharmProjects/pso-virtual-machine-resource-optimizer/.venv/lib/python3.12/site-packages/py4j/java_gateway.py", line 982, in _get_connection
    connection = self.deque.pop()
                 ^^^^^^^^^^^^^^^^
IndexError: pop from an empty deque

During handling of the above exception, another exception occurred:

Traceback (most recent call last):
  File "/Users/leandrohoenen/PycharmProjects/pso-virtual-machine-resource-optimizer/.venv/lib/python3.12/site-packages/py4j/java_gateway.py", line 1132, in start
    self.socket.connect((self.address, self.port))
ConnectionRefusedError: [Errno 61] Connection refused
2024-06-09 00:33:52,539 - pyswarms.single.global_best - INFO - Optimize for 400 iters with {'c1': 0.5, 'c2': 0.3, 'w': 0.9}
2024-06-09 00:34:25,364 - py4j.java_gateway - INFO - Error while receiving.
Traceback (most recent call last):
  File "/Users/leandrohoenen/PycharmProjects/pso-virtual-machine-resource-optimizer/.venv/lib/python3.12/site-packages/py4j/java_gateway.py", line 1224, in send_command
    raise Py4JNetworkError("Answer from Java side is empty")
py4j.protocol.Py4JNetworkError: Answer from Java side is empty
2024-06-09 00:34:25,368 - root - ERROR - Exception while sending command.
Traceback (most recent call last):
  File "/Users/leandrohoenen/PycharmProjects/pso-virtual-machine-resource-optimizer/.venv/lib/python3.12/site-packages/py4j/java_gateway.py", line 1224, in send_command
    raise Py4JNetworkError("Answer from Java side is empty")
py4j.protocol.Py4JNetworkError: Answer from Java side is empty

During handling of the above exception, another exception occurred:

Traceback (most recent call last):
  File "/Users/leandrohoenen/PycharmProjects/pso-virtual-machine-resource-optimizer/.venv/lib/python3.12/site-packages/py4j/java_gateway.py", line 1038, in send_command
    response = connection.send_command(command)
               ^^^^^^^^^^^^^^^^^^^^^^^^^^^^^^^^
  File "/Users/leandrohoenen/PycharmProjects/pso-virtual-machine-resource-optimizer/.venv/lib/python3.12/site-packages/py4j/java_gateway.py", line 1228, in send_command
    raise Py4JNetworkError(
py4j.protocol.Py4JNetworkError: Error while receiving
2024-06-09 00:34:25,370 - py4j.java_gateway - ERROR - An error occurred while trying to connect to the Java server (127.0.0.1:25333)
Traceback (most recent call last):
  File "/Users/leandrohoenen/PycharmProjects/pso-virtual-machine-resource-optimizer/.venv/lib/python3.12/site-packages/py4j/java_gateway.py", line 982, in _get_connection
    connection = self.deque.pop()
                 ^^^^^^^^^^^^^^^^
IndexError: pop from an empty deque

During handling of the above exception, another exception occurred:

Traceback (most recent call last):
  File "/Users/leandrohoenen/PycharmProjects/pso-virtual-machine-resource-optimizer/.venv/lib/python3.12/site-packages/py4j/java_gateway.py", line 1132, in start
    self.socket.connect((self.address, self.port))
ConnectionRefusedError: [Errno 61] Connection refused
2024-06-09 00:34:25,370 - py4j.java_gateway - ERROR - An error occurred while trying to connect to the Java server (127.0.0.1:25333)
Traceback (most recent call last):
  File "/Users/leandrohoenen/PycharmProjects/pso-virtual-machine-resource-optimizer/.venv/lib/python3.12/site-packages/py4j/java_gateway.py", line 982, in _get_connection
    connection = self.deque.pop()
                 ^^^^^^^^^^^^^^^^
IndexError: pop from an empty deque

During handling of the above exception, another exception occurred:

Traceback (most recent call last):
  File "/Users/leandrohoenen/PycharmProjects/pso-virtual-machine-resource-optimizer/.venv/lib/python3.12/site-packages/py4j/java_gateway.py", line 1132, in start
    self.socket.connect((self.address, self.port))
ConnectionRefusedError: [Errno 61] Connection refused
2024-06-09 00:34:25,371 - py4j.java_gateway - ERROR - An error occurred while trying to connect to the Java server (127.0.0.1:25333)
Traceback (most recent call last):
  File "/Users/leandrohoenen/PycharmProjects/pso-virtual-machine-resource-optimizer/.venv/lib/python3.12/site-packages/py4j/java_gateway.py", line 982, in _get_connection
    connection = self.deque.pop()
                 ^^^^^^^^^^^^^^^^
IndexError: pop from an empty deque

During handling of the above exception, another exception occurred:

Traceback (most recent call last):
  File "/Users/leandrohoenen/PycharmProjects/pso-virtual-machine-resource-optimizer/.venv/lib/python3.12/site-packages/py4j/java_gateway.py", line 1132, in start
    self.socket.connect((self.address, self.port))
ConnectionRefusedError: [Errno 61] Connection refused
2024-06-09 00:34:25,371 - py4j.java_gateway - ERROR - An error occurred while trying to connect to the Java server (127.0.0.1:25333)
Traceback (most recent call last):
  File "/Users/leandrohoenen/PycharmProjects/pso-virtual-machine-resource-optimizer/.venv/lib/python3.12/site-packages/py4j/java_gateway.py", line 982, in _get_connection
    connection = self.deque.pop()
                 ^^^^^^^^^^^^^^^^
IndexError: pop from an empty deque

During handling of the above exception, another exception occurred:

Traceback (most recent call last):
  File "/Users/leandrohoenen/PycharmProjects/pso-virtual-machine-resource-optimizer/.venv/lib/python3.12/site-packages/py4j/java_gateway.py", line 1132, in start
    self.socket.connect((self.address, self.port))
ConnectionRefusedError: [Errno 61] Connection refused
2024-06-09 00:34:25,372 - py4j.java_gateway - ERROR - An error occurred while trying to connect to the Java server (127.0.0.1:25333)
Traceback (most recent call last):
  File "/Users/leandrohoenen/PycharmProjects/pso-virtual-machine-resource-optimizer/.venv/lib/python3.12/site-packages/py4j/java_gateway.py", line 982, in _get_connection
    connection = self.deque.pop()
                 ^^^^^^^^^^^^^^^^
IndexError: pop from an empty deque

During handling of the above exception, another exception occurred:

Traceback (most recent call last):
  File "/Users/leandrohoenen/PycharmProjects/pso-virtual-machine-resource-optimizer/.venv/lib/python3.12/site-packages/py4j/java_gateway.py", line 1132, in start
    self.socket.connect((self.address, self.port))
ConnectionRefusedError: [Errno 61] Connection refused
2024-06-09 00:34:25,372 - py4j.java_gateway - ERROR - An error occurred while trying to connect to the Java server (127.0.0.1:25333)
Traceback (most recent call last):
  File "/Users/leandrohoenen/PycharmProjects/pso-virtual-machine-resource-optimizer/.venv/lib/python3.12/site-packages/py4j/java_gateway.py", line 982, in _get_connection
    connection = self.deque.pop()
                 ^^^^^^^^^^^^^^^^
IndexError: pop from an empty deque

During handling of the above exception, another exception occurred:

Traceback (most recent call last):
  File "/Users/leandrohoenen/PycharmProjects/pso-virtual-machine-resource-optimizer/.venv/lib/python3.12/site-packages/py4j/java_gateway.py", line 1132, in start
    self.socket.connect((self.address, self.port))
ConnectionRefusedError: [Errno 61] Connection refused
2024-06-09 00:34:25,372 - py4j.java_gateway - ERROR - An error occurred while trying to connect to the Java server (127.0.0.1:25333)
Traceback (most recent call last):
  File "/Users/leandrohoenen/PycharmProjects/pso-virtual-machine-resource-optimizer/.venv/lib/python3.12/site-packages/py4j/java_gateway.py", line 982, in _get_connection
    connection = self.deque.pop()
                 ^^^^^^^^^^^^^^^^
IndexError: pop from an empty deque

During handling of the above exception, another exception occurred:

Traceback (most recent call last):
  File "/Users/leandrohoenen/PycharmProjects/pso-virtual-machine-resource-optimizer/.venv/lib/python3.12/site-packages/py4j/java_gateway.py", line 1132, in start
    self.socket.connect((self.address, self.port))
ConnectionRefusedError: [Errno 61] Connection refused
2024-06-09 00:34:25,373 - py4j.java_gateway - ERROR - An error occurred while trying to connect to the Java server (127.0.0.1:25333)
Traceback (most recent call last):
  File "/Users/leandrohoenen/PycharmProjects/pso-virtual-machine-resource-optimizer/.venv/lib/python3.12/site-packages/py4j/java_gateway.py", line 982, in _get_connection
    connection = self.deque.pop()
                 ^^^^^^^^^^^^^^^^
IndexError: pop from an empty deque

During handling of the above exception, another exception occurred:

Traceback (most recent call last):
  File "/Users/leandrohoenen/PycharmProjects/pso-virtual-machine-resource-optimizer/.venv/lib/python3.12/site-packages/py4j/java_gateway.py", line 1132, in start
    self.socket.connect((self.address, self.port))
ConnectionRefusedError: [Errno 61] Connection refused
2024-06-09 00:34:25,373 - py4j.java_gateway - ERROR - An error occurred while trying to connect to the Java server (127.0.0.1:25333)
Traceback (most recent call last):
  File "/Users/leandrohoenen/PycharmProjects/pso-virtual-machine-resource-optimizer/.venv/lib/python3.12/site-packages/py4j/java_gateway.py", line 982, in _get_connection
    connection = self.deque.pop()
                 ^^^^^^^^^^^^^^^^
IndexError: pop from an empty deque

During handling of the above exception, another exception occurred:

Traceback (most recent call last):
  File "/Users/leandrohoenen/PycharmProjects/pso-virtual-machine-resource-optimizer/.venv/lib/python3.12/site-packages/py4j/java_gateway.py", line 1132, in start
    self.socket.connect((self.address, self.port))
ConnectionRefusedError: [Errno 61] Connection refused
2024-06-09 00:34:25,374 - py4j.java_gateway - ERROR - An error occurred while trying to connect to the Java server (127.0.0.1:25333)
Traceback (most recent call last):
  File "/Users/leandrohoenen/PycharmProjects/pso-virtual-machine-resource-optimizer/.venv/lib/python3.12/site-packages/py4j/java_gateway.py", line 982, in _get_connection
    connection = self.deque.pop()
                 ^^^^^^^^^^^^^^^^
IndexError: pop from an empty deque

During handling of the above exception, another exception occurred:

Traceback (most recent call last):
  File "/Users/leandrohoenen/PycharmProjects/pso-virtual-machine-resource-optimizer/.venv/lib/python3.12/site-packages/py4j/java_gateway.py", line 1132, in start
    self.socket.connect((self.address, self.port))
ConnectionRefusedError: [Errno 61] Connection refused
2024-06-09 00:34:25,374 - py4j.java_gateway - ERROR - An error occurred while trying to connect to the Java server (127.0.0.1:25333)
Traceback (most recent call last):
  File "/Users/leandrohoenen/PycharmProjects/pso-virtual-machine-resource-optimizer/.venv/lib/python3.12/site-packages/py4j/java_gateway.py", line 982, in _get_connection
    connection = self.deque.pop()
                 ^^^^^^^^^^^^^^^^
IndexError: pop from an empty deque

During handling of the above exception, another exception occurred:

Traceback (most recent call last):
  File "/Users/leandrohoenen/PycharmProjects/pso-virtual-machine-resource-optimizer/.venv/lib/python3.12/site-packages/py4j/java_gateway.py", line 1132, in start
    self.socket.connect((self.address, self.port))
ConnectionRefusedError: [Errno 61] Connection refused
2024-06-09 00:34:25,375 - py4j.java_gateway - ERROR - An error occurred while trying to connect to the Java server (127.0.0.1:25333)
Traceback (most recent call last):
  File "/Users/leandrohoenen/PycharmProjects/pso-virtual-machine-resource-optimizer/.venv/lib/python3.12/site-packages/py4j/java_gateway.py", line 982, in _get_connection
    connection = self.deque.pop()
                 ^^^^^^^^^^^^^^^^
IndexError: pop from an empty deque

During handling of the above exception, another exception occurred:

Traceback (most recent call last):
  File "/Users/leandrohoenen/PycharmProjects/pso-virtual-machine-resource-optimizer/.venv/lib/python3.12/site-packages/py4j/java_gateway.py", line 1132, in start
    self.socket.connect((self.address, self.port))
ConnectionRefusedError: [Errno 61] Connection refused
2024-06-09 00:34:25,375 - py4j.java_gateway - ERROR - An error occurred while trying to connect to the Java server (127.0.0.1:25333)
Traceback (most recent call last):
  File "/Users/leandrohoenen/PycharmProjects/pso-virtual-machine-resource-optimizer/.venv/lib/python3.12/site-packages/py4j/java_gateway.py", line 982, in _get_connection
    connection = self.deque.pop()
                 ^^^^^^^^^^^^^^^^
IndexError: pop from an empty deque

During handling of the above exception, another exception occurred:

Traceback (most recent call last):
  File "/Users/leandrohoenen/PycharmProjects/pso-virtual-machine-resource-optimizer/.venv/lib/python3.12/site-packages/py4j/java_gateway.py", line 1132, in start
    self.socket.connect((self.address, self.port))
ConnectionRefusedError: [Errno 61] Connection refused
2024-06-09 00:34:25,375 - py4j.java_gateway - ERROR - An error occurred while trying to connect to the Java server (127.0.0.1:25333)
Traceback (most recent call last):
  File "/Users/leandrohoenen/PycharmProjects/pso-virtual-machine-resource-optimizer/.venv/lib/python3.12/site-packages/py4j/java_gateway.py", line 982, in _get_connection
    connection = self.deque.pop()
                 ^^^^^^^^^^^^^^^^
IndexError: pop from an empty deque

During handling of the above exception, another exception occurred:

Traceback (most recent call last):
  File "/Users/leandrohoenen/PycharmProjects/pso-virtual-machine-resource-optimizer/.venv/lib/python3.12/site-packages/py4j/java_gateway.py", line 1132, in start
    self.socket.connect((self.address, self.port))
ConnectionRefusedError: [Errno 61] Connection refused
2024-06-09 00:34:25,376 - py4j.java_gateway - ERROR - An error occurred while trying to connect to the Java server (127.0.0.1:25333)
Traceback (most recent call last):
  File "/Users/leandrohoenen/PycharmProjects/pso-virtual-machine-resource-optimizer/.venv/lib/python3.12/site-packages/py4j/java_gateway.py", line 982, in _get_connection
    connection = self.deque.pop()
                 ^^^^^^^^^^^^^^^^
IndexError: pop from an empty deque

During handling of the above exception, another exception occurred:

Traceback (most recent call last):
  File "/Users/leandrohoenen/PycharmProjects/pso-virtual-machine-resource-optimizer/.venv/lib/python3.12/site-packages/py4j/java_gateway.py", line 1132, in start
    self.socket.connect((self.address, self.port))
ConnectionRefusedError: [Errno 61] Connection refused
2024-06-09 00:34:25,376 - py4j.java_gateway - ERROR - An error occurred while trying to connect to the Java server (127.0.0.1:25333)
Traceback (most recent call last):
  File "/Users/leandrohoenen/PycharmProjects/pso-virtual-machine-resource-optimizer/.venv/lib/python3.12/site-packages/py4j/java_gateway.py", line 982, in _get_connection
    connection = self.deque.pop()
                 ^^^^^^^^^^^^^^^^
IndexError: pop from an empty deque

During handling of the above exception, another exception occurred:

Traceback (most recent call last):
  File "/Users/leandrohoenen/PycharmProjects/pso-virtual-machine-resource-optimizer/.venv/lib/python3.12/site-packages/py4j/java_gateway.py", line 1132, in start
    self.socket.connect((self.address, self.port))
ConnectionRefusedError: [Errno 61] Connection refused
2024-06-09 00:34:25,377 - py4j.java_gateway - ERROR - An error occurred while trying to connect to the Java server (127.0.0.1:25333)
Traceback (most recent call last):
  File "/Users/leandrohoenen/PycharmProjects/pso-virtual-machine-resource-optimizer/.venv/lib/python3.12/site-packages/py4j/java_gateway.py", line 982, in _get_connection
    connection = self.deque.pop()
                 ^^^^^^^^^^^^^^^^
IndexError: pop from an empty deque

During handling of the above exception, another exception occurred:

Traceback (most recent call last):
  File "/Users/leandrohoenen/PycharmProjects/pso-virtual-machine-resource-optimizer/.venv/lib/python3.12/site-packages/py4j/java_gateway.py", line 1132, in start
    self.socket.connect((self.address, self.port))
ConnectionRefusedError: [Errno 61] Connection refused
2024-06-09 00:34:25,377 - py4j.java_gateway - ERROR - An error occurred while trying to connect to the Java server (127.0.0.1:25333)
Traceback (most recent call last):
  File "/Users/leandrohoenen/PycharmProjects/pso-virtual-machine-resource-optimizer/.venv/lib/python3.12/site-packages/py4j/java_gateway.py", line 982, in _get_connection
    connection = self.deque.pop()
                 ^^^^^^^^^^^^^^^^
IndexError: pop from an empty deque

During handling of the above exception, another exception occurred:

Traceback (most recent call last):
  File "/Users/leandrohoenen/PycharmProjects/pso-virtual-machine-resource-optimizer/.venv/lib/python3.12/site-packages/py4j/java_gateway.py", line 1132, in start
    self.socket.connect((self.address, self.port))
ConnectionRefusedError: [Errno 61] Connection refused
2024-06-09 00:34:25,378 - py4j.java_gateway - ERROR - An error occurred while trying to connect to the Java server (127.0.0.1:25333)
Traceback (most recent call last):
  File "/Users/leandrohoenen/PycharmProjects/pso-virtual-machine-resource-optimizer/.venv/lib/python3.12/site-packages/py4j/java_gateway.py", line 982, in _get_connection
    connection = self.deque.pop()
                 ^^^^^^^^^^^^^^^^
IndexError: pop from an empty deque

During handling of the above exception, another exception occurred:

Traceback (most recent call last):
  File "/Users/leandrohoenen/PycharmProjects/pso-virtual-machine-resource-optimizer/.venv/lib/python3.12/site-packages/py4j/java_gateway.py", line 1132, in start
    self.socket.connect((self.address, self.port))
ConnectionRefusedError: [Errno 61] Connection refused
2024-06-09 00:34:25,378 - py4j.java_gateway - ERROR - An error occurred while trying to connect to the Java server (127.0.0.1:25333)
Traceback (most recent call last):
  File "/Users/leandrohoenen/PycharmProjects/pso-virtual-machine-resource-optimizer/.venv/lib/python3.12/site-packages/py4j/java_gateway.py", line 982, in _get_connection
    connection = self.deque.pop()
                 ^^^^^^^^^^^^^^^^
IndexError: pop from an empty deque

During handling of the above exception, another exception occurred:

Traceback (most recent call last):
  File "/Users/leandrohoenen/PycharmProjects/pso-virtual-machine-resource-optimizer/.venv/lib/python3.12/site-packages/py4j/java_gateway.py", line 1132, in start
    self.socket.connect((self.address, self.port))
ConnectionRefusedError: [Errno 61] Connection refused
2024-06-09 00:34:25,378 - py4j.java_gateway - ERROR - An error occurred while trying to connect to the Java server (127.0.0.1:25333)
Traceback (most recent call last):
  File "/Users/leandrohoenen/PycharmProjects/pso-virtual-machine-resource-optimizer/.venv/lib/python3.12/site-packages/py4j/java_gateway.py", line 982, in _get_connection
    connection = self.deque.pop()
                 ^^^^^^^^^^^^^^^^
IndexError: pop from an empty deque

During handling of the above exception, another exception occurred:

Traceback (most recent call last):
  File "/Users/leandrohoenen/PycharmProjects/pso-virtual-machine-resource-optimizer/.venv/lib/python3.12/site-packages/py4j/java_gateway.py", line 1132, in start
    self.socket.connect((self.address, self.port))
ConnectionRefusedError: [Errno 61] Connection refused
2024-06-09 00:34:25,379 - py4j.java_gateway - ERROR - An error occurred while trying to connect to the Java server (127.0.0.1:25333)
Traceback (most recent call last):
  File "/Users/leandrohoenen/PycharmProjects/pso-virtual-machine-resource-optimizer/.venv/lib/python3.12/site-packages/py4j/java_gateway.py", line 982, in _get_connection
    connection = self.deque.pop()
                 ^^^^^^^^^^^^^^^^
IndexError: pop from an empty deque

During handling of the above exception, another exception occurred:

Traceback (most recent call last):
  File "/Users/leandrohoenen/PycharmProjects/pso-virtual-machine-resource-optimizer/.venv/lib/python3.12/site-packages/py4j/java_gateway.py", line 1132, in start
    self.socket.connect((self.address, self.port))
ConnectionRefusedError: [Errno 61] Connection refused
2024-06-09 00:34:25,379 - py4j.java_gateway - ERROR - An error occurred while trying to connect to the Java server (127.0.0.1:25333)
Traceback (most recent call last):
  File "/Users/leandrohoenen/PycharmProjects/pso-virtual-machine-resource-optimizer/.venv/lib/python3.12/site-packages/py4j/java_gateway.py", line 982, in _get_connection
    connection = self.deque.pop()
                 ^^^^^^^^^^^^^^^^
IndexError: pop from an empty deque

During handling of the above exception, another exception occurred:

Traceback (most recent call last):
  File "/Users/leandrohoenen/PycharmProjects/pso-virtual-machine-resource-optimizer/.venv/lib/python3.12/site-packages/py4j/java_gateway.py", line 1132, in start
    self.socket.connect((self.address, self.port))
ConnectionRefusedError: [Errno 61] Connection refused
2024-06-09 00:34:25,380 - py4j.java_gateway - ERROR - An error occurred while trying to connect to the Java server (127.0.0.1:25333)
Traceback (most recent call last):
  File "/Users/leandrohoenen/PycharmProjects/pso-virtual-machine-resource-optimizer/.venv/lib/python3.12/site-packages/py4j/java_gateway.py", line 982, in _get_connection
    connection = self.deque.pop()
                 ^^^^^^^^^^^^^^^^
IndexError: pop from an empty deque

During handling of the above exception, another exception occurred:

Traceback (most recent call last):
  File "/Users/leandrohoenen/PycharmProjects/pso-virtual-machine-resource-optimizer/.venv/lib/python3.12/site-packages/py4j/java_gateway.py", line 1132, in start
    self.socket.connect((self.address, self.port))
ConnectionRefusedError: [Errno 61] Connection refused
2024-06-09 00:34:25,380 - py4j.java_gateway - ERROR - An error occurred while trying to connect to the Java server (127.0.0.1:25333)
Traceback (most recent call last):
  File "/Users/leandrohoenen/PycharmProjects/pso-virtual-machine-resource-optimizer/.venv/lib/python3.12/site-packages/py4j/java_gateway.py", line 982, in _get_connection
    connection = self.deque.pop()
                 ^^^^^^^^^^^^^^^^
IndexError: pop from an empty deque

During handling of the above exception, another exception occurred:

Traceback (most recent call last):
  File "/Users/leandrohoenen/PycharmProjects/pso-virtual-machine-resource-optimizer/.venv/lib/python3.12/site-packages/py4j/java_gateway.py", line 1132, in start
    self.socket.connect((self.address, self.port))
ConnectionRefusedError: [Errno 61] Connection refused
2024-06-09 00:34:25,380 - py4j.java_gateway - ERROR - An error occurred while trying to connect to the Java server (127.0.0.1:25333)
Traceback (most recent call last):
  File "/Users/leandrohoenen/PycharmProjects/pso-virtual-machine-resource-optimizer/.venv/lib/python3.12/site-packages/py4j/java_gateway.py", line 982, in _get_connection
    connection = self.deque.pop()
                 ^^^^^^^^^^^^^^^^
IndexError: pop from an empty deque

During handling of the above exception, another exception occurred:

Traceback (most recent call last):
  File "/Users/leandrohoenen/PycharmProjects/pso-virtual-machine-resource-optimizer/.venv/lib/python3.12/site-packages/py4j/java_gateway.py", line 1132, in start
    self.socket.connect((self.address, self.port))
ConnectionRefusedError: [Errno 61] Connection refused
2024-06-09 00:34:25,381 - py4j.java_gateway - ERROR - An error occurred while trying to connect to the Java server (127.0.0.1:25333)
Traceback (most recent call last):
  File "/Users/leandrohoenen/PycharmProjects/pso-virtual-machine-resource-optimizer/.venv/lib/python3.12/site-packages/py4j/java_gateway.py", line 982, in _get_connection
    connection = self.deque.pop()
                 ^^^^^^^^^^^^^^^^
IndexError: pop from an empty deque

During handling of the above exception, another exception occurred:

Traceback (most recent call last):
  File "/Users/leandrohoenen/PycharmProjects/pso-virtual-machine-resource-optimizer/.venv/lib/python3.12/site-packages/py4j/java_gateway.py", line 1132, in start
    self.socket.connect((self.address, self.port))
ConnectionRefusedError: [Errno 61] Connection refused
2024-06-09 00:34:25,381 - py4j.java_gateway - ERROR - An error occurred while trying to connect to the Java server (127.0.0.1:25333)
Traceback (most recent call last):
  File "/Users/leandrohoenen/PycharmProjects/pso-virtual-machine-resource-optimizer/.venv/lib/python3.12/site-packages/py4j/java_gateway.py", line 982, in _get_connection
    connection = self.deque.pop()
                 ^^^^^^^^^^^^^^^^
IndexError: pop from an empty deque

During handling of the above exception, another exception occurred:

Traceback (most recent call last):
  File "/Users/leandrohoenen/PycharmProjects/pso-virtual-machine-resource-optimizer/.venv/lib/python3.12/site-packages/py4j/java_gateway.py", line 1132, in start
    self.socket.connect((self.address, self.port))
ConnectionRefusedError: [Errno 61] Connection refused
2024-06-09 00:34:25,382 - py4j.java_gateway - ERROR - An error occurred while trying to connect to the Java server (127.0.0.1:25333)
Traceback (most recent call last):
  File "/Users/leandrohoenen/PycharmProjects/pso-virtual-machine-resource-optimizer/.venv/lib/python3.12/site-packages/py4j/java_gateway.py", line 982, in _get_connection
    connection = self.deque.pop()
                 ^^^^^^^^^^^^^^^^
IndexError: pop from an empty deque

During handling of the above exception, another exception occurred:

Traceback (most recent call last):
  File "/Users/leandrohoenen/PycharmProjects/pso-virtual-machine-resource-optimizer/.venv/lib/python3.12/site-packages/py4j/java_gateway.py", line 1132, in start
    self.socket.connect((self.address, self.port))
ConnectionRefusedError: [Errno 61] Connection refused
2024-06-09 00:34:25,415 - py4j.java_gateway - ERROR - An error occurred while trying to connect to the Java server (127.0.0.1:25333)
Traceback (most recent call last):
  File "/Users/leandrohoenen/PycharmProjects/pso-virtual-machine-resource-optimizer/.venv/lib/python3.12/site-packages/py4j/java_gateway.py", line 982, in _get_connection
    connection = self.deque.pop()
                 ^^^^^^^^^^^^^^^^
IndexError: pop from an empty deque

During handling of the above exception, another exception occurred:

Traceback (most recent call last):
  File "/Users/leandrohoenen/PycharmProjects/pso-virtual-machine-resource-optimizer/.venv/lib/python3.12/site-packages/py4j/java_gateway.py", line 1132, in start
    self.socket.connect((self.address, self.port))
ConnectionRefusedError: [Errno 61] Connection refused
2024-06-09 00:37:32,805 - py4j.java_gateway - ERROR - An error occurred while trying to connect to the Java server (127.0.0.1:25333)
Traceback (most recent call last):
  File "/Users/leandrohoenen/PycharmProjects/pso-virtual-machine-resource-optimizer/.venv/lib/python3.12/site-packages/py4j/java_gateway.py", line 982, in _get_connection
    connection = self.deque.pop()
                 ^^^^^^^^^^^^^^^^
IndexError: pop from an empty deque

During handling of the above exception, another exception occurred:

Traceback (most recent call last):
  File "/Users/leandrohoenen/PycharmProjects/pso-virtual-machine-resource-optimizer/.venv/lib/python3.12/site-packages/py4j/java_gateway.py", line 1132, in start
    self.socket.connect((self.address, self.port))
ConnectionRefusedError: [Errno 61] Connection refused
2024-06-09 00:37:46,011 - pyswarms.single.global_best - INFO - Optimize for 400 iters with {'c1': 0.5, 'c2': 0.3, 'w': 0.9}
2024-06-09 00:39:10,347 - pyswarms.single.global_best - INFO - Optimize for 400 iters with {'c1': 0.5, 'c2': 0.3, 'w': 0.9}
2024-06-09 00:39:49,713 - pyswarms.single.global_best - INFO - Optimize for 400 iters with {'c1': 0.5, 'c2': 0.3, 'w': 0.9}
2024-06-09 00:40:06,452 - pyswarms.single.global_best - INFO - Optimize for 400 iters with {'c1': 0.5, 'c2': 0.3, 'w': 0.9}
2024-06-09 00:49:12,497 - pyswarms.single.global_best - INFO - Optimize for 400 iters with {'c1': 0.5, 'c2': 0.3, 'w': 0.9}
2024-06-09 00:49:16,248 - pyswarms.single.global_best - INFO - Optimization finished | best cost: 1677.7766666666666, best pos: [9.70655392 1.00084011]
2024-06-09 00:49:39,923 - pyswarms.single.global_best - INFO - Optimize for 400 iters with {'c1': 0.5, 'c2': 0.3, 'w': 0.9}
2024-06-09 00:50:42,149 - pyswarms.single.global_best - INFO - Optimize for 400 iters with {'c1': 0.5, 'c2': 0.3, 'w': 0.9}
2024-06-09 00:50:45,028 - pyswarms.single.global_best - INFO - Optimization finished | best cost: 1673.7766666666666, best pos: [5.95031171 1.0012185 ]
2024-06-09 00:51:06,033 - pyswarms.single.global_best - INFO - Optimize for 400 iters with {'c1': 0.5, 'c2': 0.3, 'w': 0.9}
2024-06-09 00:51:08,686 - pyswarms.single.global_best - INFO - Optimization finished | best cost: 1672.7766666666666, best pos: [4.91141456 1.00124064]
2024-06-09 00:51:47,956 - pyswarms.single.global_best - INFO - Optimize for 400 iters with {'c1': 0.5, 'c2': 0.3, 'w': 0.9}
2024-06-09 00:51:50,640 - pyswarms.single.global_best - INFO - Optimization finished | best cost: 1675.7766666666666, best pos: [2.60298515 1.00554935]
2024-06-09 00:52:27,838 - pyswarms.single.global_best - INFO - Optimize for 400 iters with {'c1': 0.5, 'c2': 0.3, 'w': 0.9}
2024-06-09 00:52:30,538 - pyswarms.single.global_best - INFO - Optimization finished | best cost: 1679.7766666666666, best pos: [5.25751543 1.00787253]
2024-06-09 00:52:38,673 - pyswarms.single.global_best - INFO - Optimize for 400 iters with {'c1': 0.5, 'c2': 0.3, 'w': 0.9}
2024-06-09 00:52:41,360 - pyswarms.single.global_best - INFO - Optimization finished | best cost: 1677.7766666666666, best pos: [9.73520889 1.00084768]
2024-06-09 00:55:18,985 - pyswarms.single.global_best - INFO - Optimize for 400 iters with {'c1': 0.5, 'c2': 0.3, 'w': 0.9}
2024-06-09 00:55:22,390 - pyswarms.single.global_best - INFO - Optimization finished | best cost: 1683.7766666666666, best pos: [15.83628975  1.00109678]
2024-06-09 00:58:58,873 - pyswarms.single.global_best - INFO - Optimize for 400 iters with {'c1': 0.5, 'c2': 0.3, 'w': 0.9}
2024-06-09 00:59:59,609 - pyswarms.single.global_best - INFO - Optimize for 400 iters with {'c1': 0.5, 'c2': 0.3, 'w': 0.9}
2024-06-09 01:00:03,080 - pyswarms.single.global_best - INFO - Optimization finished | best cost: 1672.7766666666666, best pos: [5.39356413 1.00112583]
2024-06-09 01:03:35,729 - pyswarms.single.global_best - INFO - Optimize for 400 iters with {'c1': 0.5, 'c2': 0.3, 'w': 0.9}
2024-06-09 01:03:39,473 - pyswarms.single.global_best - INFO - Optimization finished | best cost: 1671.7766666666666, best pos: [4.92711136 1.00021646]
2024-06-09 01:04:09,061 - pyswarms.single.global_best - INFO - Optimize for 400 iters with {'c1': 0.5, 'c2': 0.3, 'w': 0.9}
2024-06-09 01:04:11,724 - pyswarms.single.global_best - INFO - Optimization finished | best cost: 1674.7766666666666, best pos: [4.49825526 1.00428608]
2024-06-09 01:05:10,258 - pyswarms.single.global_best - INFO - Optimize for 400 iters with {'c1': 0.5, 'c2': 0.3, 'w': 0.9}
2024-06-09 01:05:12,880 - pyswarms.single.global_best - INFO - Optimization finished | best cost: 1681.7766666666666, best pos: [12.77539309  1.00216856]
2024-06-09 01:05:27,535 - pyswarms.single.global_best - INFO - Optimize for 1000 iters with {'c1': 0.5, 'c2': 0.3, 'w': 0.9}
2024-06-09 01:05:33,299 - pyswarms.single.global_best - INFO - Optimization finished | best cost: 1669.7766666666666, best pos: [2.82349527 1.00039024]
2024-06-09 01:05:38,070 - pyswarms.single.global_best - INFO - Optimize for 1000 iters with {'c1': 0.5, 'c2': 0.3, 'w': 0.9}
2024-06-09 01:05:43,778 - pyswarms.single.global_best - INFO - Optimization finished | best cost: 1676.7766666666666, best pos: [10.46957514  1.00000918]
2024-06-09 01:05:53,358 - pyswarms.single.global_best - INFO - Optimize for 1000 iters with {'c1': 0.5, 'c2': 0.3, 'w': 0.9}
2024-06-09 01:05:59,113 - pyswarms.single.global_best - INFO - Optimization finished | best cost: 1675.7766666666666, best pos: [5.11924684 1.00425677]
2024-06-09 01:06:01,987 - pyswarms.single.global_best - INFO - Optimize for 1000 iters with {'c1': 0.5, 'c2': 0.3, 'w': 0.9}
2024-06-09 01:06:07,745 - pyswarms.single.global_best - INFO - Optimization finished | best cost: 1671.7766666666666, best pos: [3.27781085 1.00179095]
2024-06-09 01:06:19,895 - pyswarms.single.global_best - INFO - Optimize for 1000 iters with {'c1': 0.5, 'c2': 0.3, 'w': 0.9}
2024-06-09 01:06:25,633 - pyswarms.single.global_best - INFO - Optimization finished | best cost: 1678.7766666666666, best pos: [7.19684635 1.00505862]
2024-06-09 01:06:38,501 - pyswarms.single.global_best - INFO - Optimize for 1000 iters with {'c1': 0.5, 'c2': 0.3, 'w': 0.9}
2024-06-09 01:06:44,215 - pyswarms.single.global_best - INFO - Optimization finished | best cost: 1684.7766666666666, best pos: [15.6649621   1.00240533]
2024-06-09 01:06:46,631 - pyswarms.single.global_best - INFO - Optimize for 1000 iters with {'c1': 0.5, 'c2': 0.3, 'w': 0.9}
2024-06-09 01:06:52,420 - pyswarms.single.global_best - INFO - Optimization finished | best cost: 1677.7766666666666, best pos: [9.07499575 1.00154066]
2024-06-09 01:07:39,322 - pyswarms.single.global_best - INFO - Optimize for 1000 iters with {'c1': 0.5, 'c2': 0.3, 'w': 0.9}
2024-06-09 01:07:45,198 - pyswarms.single.global_best - INFO - Optimization finished | best cost: 101400.111, best pos: [1.92451558 1.00197181]
2024-06-09 01:07:51,376 - pyswarms.single.global_best - INFO - Optimize for 1000 iters with {'c1': 0.5, 'c2': 0.3, 'w': 0.9}
2024-06-09 01:07:57,084 - pyswarms.single.global_best - INFO - Optimization finished | best cost: 101266.77666666667, best pos: [5.27476954 1.0009274 ]
2024-06-09 01:08:00,591 - pyswarms.single.global_best - INFO - Optimize for 1000 iters with {'c1': 0.5, 'c2': 0.3, 'w': 0.9}
2024-06-09 01:08:06,299 - pyswarms.single.global_best - INFO - Optimization finished | best cost: 101666.77666666667, best pos: [10.36728147  1.00048127]
2024-06-09 01:09:32,789 - pyswarms.single.global_best - INFO - Optimize for 1000 iters with {'c1': 0.5, 'c2': 0.3, 'w': 0.9}
2024-06-09 01:09:38,568 - pyswarms.single.global_best - INFO - Optimization finished | best cost: 6320.710666666667, best pos: [6.92693788 1.00202541]
2024-06-09 01:10:58,334 - pyswarms.single.global_best - INFO - Optimize for 1000 iters with {'c1': 0.5, 'c2': 0.3, 'w': 0.9}
2024-06-09 01:11:04,079 - pyswarms.single.global_best - INFO - Optimization finished | best cost: 61569.63451851852, best pos: [9.09356937 1.00038781]
2024-06-09 01:11:07,845 - pyswarms.single.global_best - INFO - Optimize for 1000 iters with {'c1': 0.5, 'c2': 0.3, 'w': 0.9}
2024-06-09 01:11:13,567 - pyswarms.single.global_best - INFO - Optimization finished | best cost: 61580.10152380952, best pos: [7.23513615 1.00150416]
2024-06-09 01:11:16,284 - pyswarms.single.global_best - INFO - Optimize for 1000 iters with {'c1': 0.5, 'c2': 0.3, 'w': 0.9}
2024-06-09 01:11:22,032 - pyswarms.single.global_best - INFO - Optimization finished | best cost: 61800.5162051282, best pos: [13.21280605  1.00032481]
2024-06-09 01:11:24,998 - pyswarms.single.global_best - INFO - Optimize for 1000 iters with {'c1': 0.5, 'c2': 0.3, 'w': 0.9}
2024-06-09 01:11:30,687 - pyswarms.single.global_best - INFO - Optimization finished | best cost: 61861.5162051282, best pos: [12.67588808  1.0013858 ]
2024-06-09 01:11:43,534 - pyswarms.single.global_best - INFO - Optimize for 1000 iters with {'c1': 0.5, 'c2': 0.3, 'w': 0.9}
2024-06-09 01:12:54,316 - pyswarms.single.global_best - INFO - Optimize for 1000 iters with {'c1': 0.5, 'c2': 0.3, 'w': 0.9}
2024-06-09 01:13:00,143 - pyswarms.single.global_best - INFO - Optimization finished | best cost: 1523.3906284904594, best pos: [7.40115352 1.00481841]
2024-06-09 01:13:28,688 - pyswarms.single.global_best - INFO - Optimize for 1000 iters with {'c1': 0.5, 'c2': 0.3, 'w': 0.9}
2024-06-09 01:13:34,439 - pyswarms.single.global_best - INFO - Optimization finished | best cost: 1329.9509446328116, best pos: [2.93786053 1.00078982]
2024-06-09 01:37:52,940 - pyswarms.single.global_best - INFO - Optimize for 1000 iters with {'c1': 0.5, 'c2': 0.3, 'w': 0.9}
2024-06-09 01:37:58,655 - pyswarms.single.global_best - INFO - Optimization finished | best cost: 1475.0330313753843, best pos: [6.11277829 1.00968756]
2024-06-09 01:38:13,780 - pyswarms.single.global_best - INFO - Optimize for 1000 iters with {'c1': 0.5, 'c2': 0.3, 'w': 0.9}
2024-06-09 01:38:19,548 - pyswarms.single.global_best - INFO - Optimization finished | best cost: 1367.7362109081716, best pos: [4.43224604 1.00097574]
2024-06-09 01:38:25,311 - pyswarms.single.global_best - INFO - Optimize for 1000 iters with {'c1': 0.5, 'c2': 0.3, 'w': 0.9}
2024-06-09 01:38:31,064 - pyswarms.single.global_best - INFO - Optimization finished | best cost: 1331.0232945756557, best pos: [3.46640628 1.00199565]
2024-06-09 12:58:09,591 - pyswarms.single.global_best - INFO - Optimize for 1000 iters with {'c1': 0.5, 'c2': 0.3, 'w': 0.9}
2024-06-09 12:58:16,822 - pyswarms.single.global_best - INFO - Optimization finished | best cost: 1331.0424629212778, best pos: [2.92792762 1.00231512]
2024-06-09 12:58:27,923 - pyswarms.single.global_best - INFO - Optimize for 1000 iters with {'c1': 0.5, 'c2': 0.3, 'w': 0.9}
2024-06-09 12:58:33,708 - pyswarms.single.global_best - INFO - Optimization finished | best cost: 1332.054084284795, best pos: [3.43199414 1.00250881]
2024-06-09 12:58:40,169 - pyswarms.single.global_best - INFO - Optimize for 1000 iters with {'c1': 0.5, 'c2': 0.3, 'w': 0.9}
2024-06-09 12:58:45,916 - pyswarms.single.global_best - INFO - Optimization finished | best cost: 1338.4204912522846, best pos: [3.43674046 1.00861559]
2024-06-09 12:59:10,958 - pyswarms.single.global_best - INFO - Optimize for 1000 iters with {'c1': 0.5, 'c2': 0.3, 'w': 0.9}
2024-06-09 12:59:16,736 - pyswarms.single.global_best - INFO - Optimization finished | best cost: 1342.702816191841, best pos: [2.84503331 1.01332101]
2024-06-09 13:00:41,756 - pyswarms.single.global_best - INFO - Optimize for 1000 iters with {'c1': 0.5, 'c2': 0.3, 'w': 0.9}
2024-06-09 13:00:47,752 - pyswarms.single.global_best - INFO - Optimization finished | best cost: 1334.2095962077651, best pos: [3.00439824 1.00510068]
2024-06-09 13:01:31,056 - pyswarms.single.global_best - INFO - Optimize for 1000 iters with {'c1': 0.5, 'c2': 0.3, 'w': 0.9}
2024-06-09 13:01:36,956 - pyswarms.single.global_best - INFO - Optimization finished | best cost: 1633.43862464754, best pos: [10.94812392  1.00261189]
2024-06-09 13:02:37,107 - pyswarms.single.global_best - INFO - Optimize for 1000 iters with {'c1': 0.5, 'c2': 0.3, 'w': 0.9}
2024-06-09 13:02:43,363 - pyswarms.single.global_best - INFO - Optimization finished | best cost: 1560.3361472936701, best pos: [9.42463905 1.00134221]
2024-06-09 13:03:19,513 - pyswarms.single.global_best - INFO - Optimize for 1000 iters with {'c1': 0.5, 'c2': 0.3, 'w': 0.9}
2024-06-09 13:03:25,411 - pyswarms.single.global_best - INFO - Optimization finished | best cost: 1508.442478030581, best pos: [5.17968853 1.00818956]
2024-06-09 13:05:40,548 - pyswarms.single.global_best - INFO - Optimize for 1000 iters with {'c1': 0.5, 'c2': 0.3, 'w': 0.9}
2024-06-09 13:05:46,365 - pyswarms.single.global_best - INFO - Optimization finished | best cost: 1290.9372795066388, best pos: [5.1777398  1.00370875]
2024-06-09 13:07:00,444 - pyswarms.single.global_best - INFO - Optimize for 1000 iters with {'c1': 0.5, 'c2': 0.3, 'w': 0.9}
2024-06-09 13:07:06,272 - pyswarms.single.global_best - INFO - Optimization finished | best cost: 1308.7747222222222, best pos: [6.37361884 1.00281438]
2024-06-09 13:07:13,992 - pyswarms.single.global_best - INFO - Optimize for 1000 iters with {'c1': 0.5, 'c2': 0.3, 'w': 0.9}
2024-06-09 13:08:05,150 - pyswarms.single.global_best - INFO - Optimize for 1000 iters with {'c1': 0.5, 'c2': 0.3, 'w': 0.9}
2024-06-09 13:08:11,039 - pyswarms.single.global_best - INFO - Optimization finished | best cost: 1392.1864, best pos: [5.06591186 1.00150532]
2024-06-09 13:11:14,167 - py4j.java_gateway - ERROR - An error occurred while trying to connect to the Java server (127.0.0.1:25333)
Traceback (most recent call last):
  File "/Users/leandrohoenen/PycharmProjects/pso-virtual-machine-resource-optimizer/.venv/lib/python3.12/site-packages/py4j/java_gateway.py", line 982, in _get_connection
    connection = self.deque.pop()
                 ^^^^^^^^^^^^^^^^
IndexError: pop from an empty deque

During handling of the above exception, another exception occurred:

Traceback (most recent call last):
  File "/Users/leandrohoenen/PycharmProjects/pso-virtual-machine-resource-optimizer/.venv/lib/python3.12/site-packages/py4j/java_gateway.py", line 1132, in start
    self.socket.connect((self.address, self.port))
ConnectionRefusedError: [Errno 61] Connection refused
2024-06-09 13:11:28,451 - pyswarms.single.global_best - INFO - Optimize for 500 iters with {'c1': 0.5, 'c2': 0.3, 'w': 0.9}
2024-06-09 13:11:56,779 - pyswarms.single.global_best - INFO - Optimization finished | best cost: 1390.0264, best pos: [5.46142366 1.00049529]
2024-06-09 15:23:33,585 - py4j.java_gateway - ERROR - An error occurred while trying to connect to the Java server (127.0.0.1:25333)
Traceback (most recent call last):
  File "/Users/leandrohoenen/PycharmProjects/pso-virtual-machine-resource-optimizer/.venv/lib/python3.12/site-packages/py4j/java_gateway.py", line 982, in _get_connection
    connection = self.deque.pop()
                 ^^^^^^^^^^^^^^^^
IndexError: pop from an empty deque

During handling of the above exception, another exception occurred:

Traceback (most recent call last):
  File "/Users/leandrohoenen/PycharmProjects/pso-virtual-machine-resource-optimizer/.venv/lib/python3.12/site-packages/py4j/java_gateway.py", line 1132, in start
    self.socket.connect((self.address, self.port))
ConnectionRefusedError: [Errno 61] Connection refused
2024-06-09 15:23:43,752 - pyswarms.single.global_best - INFO - Optimize for 1000 iters with {'c1': 0.5, 'c2': 0.3, 'w': 0.9}
2024-06-09 15:23:50,873 - pyswarms.single.global_best - INFO - Optimization finished | best cost: 1313.216721257988, best pos: [2.63583435 1.00174554]
2024-06-09 15:24:20,045 - pyswarms.single.global_best - INFO - Optimize for 1000 iters with {'c1': 0.5, 'c2': 0.4, 'w': 0.9}
2024-06-09 15:24:25,832 - pyswarms.single.global_best - INFO - Optimization finished | best cost: 1492.7171891687726, best pos: [8.38022417 1.00087295]
2024-06-09 15:24:36,826 - pyswarms.single.global_best - INFO - Optimize for 1000 iters with {'c1': 0.5, 'c2': 0.4, 'w': 0.9}
2024-06-09 15:24:42,696 - pyswarms.single.global_best - INFO - Optimization finished | best cost: 1326.8814904491971, best pos: [3.31070354 1.01504092]
2024-06-09 15:28:10,811 - pyswarms.single.global_best - INFO - Optimize for 1000 iters with {'c1': 0.5, 'c2': 0.4, 'w': 0.9}
2024-06-09 15:28:17,281 - pyswarms.single.global_best - INFO - Optimization finished | best cost: 656.1812222222222, best pos: [2.66791082 1.002187  ]
2024-06-09 15:40:33,024 - pyswarms.single.global_best - INFO - Optimize for 1000 iters with {'c1': 0.5, 'c2': 0.4, 'w': 0.9}
2024-06-09 15:44:41,285 - pyswarms.single.global_best - INFO - Optimize for 1000 iters with {'c1': 0.5, 'c2': 0.4, 'w': 0.9}
2024-06-09 15:44:47,384 - pyswarms.single.global_best - INFO - Optimization finished | best cost: 0.8860447866722925, best pos: [1.04213787 1.76801291]
2024-06-09 15:45:56,400 - pyswarms.single.global_best - INFO - Optimize for 1000 iters with {'c1': 0.5, 'c2': 0.4, 'w': 0.9}
2024-06-09 15:46:02,350 - pyswarms.single.global_best - INFO - Optimization finished | best cost: 0.8695965158222891, best pos: [1.25573529 1.70318875]
2024-06-09 15:47:10,886 - pyswarms.single.global_best - INFO - Optimize for 1000 iters with {'c1': 0.5, 'c2': 0.4, 'w': 0.9}
2024-06-09 15:47:16,865 - pyswarms.single.global_best - INFO - Optimization finished | best cost: 0.8955958489480196, best pos: [1.00444267 1.71446484]
2024-06-09 15:47:33,801 - pyswarms.single.global_best - INFO - Optimize for 1000 iters with {'c1': 0.5, 'c2': 0.4, 'w': 0.9}
2024-06-09 15:52:55,584 - pyswarms.single.global_best - INFO - Optimize for 1000 iters with {'c1': 0.5, 'c2': 0.4, 'w': 0.9}
2024-06-09 15:53:01,593 - pyswarms.single.global_best - INFO - Optimization finished | best cost: 2.5625928440908408, best pos: [3.16922583 2.01383459]
2024-06-09 15:53:19,300 - pyswarms.single.global_best - INFO - Optimize for 1000 iters with {'c1': 0.5, 'c2': 0.4, 'w': 0.9}
2024-06-09 15:53:25,274 - pyswarms.single.global_best - INFO - Optimization finished | best cost: 2.561735040066764, best pos: [3.31196429 2.00905031]
2024-06-09 15:58:27,788 - pyswarms.single.global_best - INFO - Optimize for 1000 iters with {'c1': 0.5, 'c2': 0.4, 'w': 0.9}
2024-06-09 15:58:33,751 - pyswarms.single.global_best - INFO - Optimization finished | best cost: 2.6121191166239823, best pos: [2.81295596 2.22292995]
2024-06-09 15:58:41,507 - pyswarms.single.global_best - INFO - Optimize for 1000 iters with {'c1': 0.5, 'c2': 0.4, 'w': 0.9}
2024-06-09 15:58:47,252 - pyswarms.single.global_best - INFO - Optimization finished | best cost: 2.7672191166239823, best pos: [3.26046977 2.73978314]
2024-06-09 15:58:56,830 - pyswarms.single.global_best - INFO - Optimize for 1000 iters with {'c1': 0.5, 'c2': 0.4, 'w': 0.9}
2024-06-09 15:59:02,748 - pyswarms.single.global_best - INFO - Optimization finished | best cost: 2.5598518650051547, best pos: [3.0386819 1.9972992]
2024-06-09 15:59:33,443 - pyswarms.single.global_best - INFO - Optimize for 500 iters with {'c1': 0.5, 'c2': 0.4, 'w': 0.9}
2024-06-09 15:59:44,592 - pyswarms.single.global_best - INFO - Optimization finished | best cost: 2.55352009064954, best pos: [3.26064279 1.92587027]
2024-06-09 15:59:52,853 - pyswarms.single.global_best - INFO - Optimize for 500 iters with {'c1': 0.5, 'c2': 0.4, 'w': 0.9}
2024-06-09 16:00:04,187 - pyswarms.single.global_best - INFO - Optimization finished | best cost: 2.5525252624137327, best pos: [2.69078277 1.92042848]
